<sdf version='1.10'>
  <world name='empty'>
    <gui fullscreen="0">
      <!-- 3D scene -->
      <plugin filename="MinimalScene" name="3D View">
        <gz-gui>
          <title>3D View</title>
          <property type="bool" key="showTitleBar">false</property>
          <property type="string" key="state">docked</property>
        </gz-gui>

        <engine>ogre2</engine>
        <scene>scene</scene>
        <ambient_light>0.4 0.4 0.4</ambient_light>
        <background_color>0.8 0.8 0.8</background_color>
        <camera_pose>-6 0 6 0 0.5 0</camera_pose>
      </plugin>

      <!-- Plugins that add functionality to the scene -->
      <plugin filename="EntityContextMenuPlugin" name="Entity context menu">
        <gz-gui>
          <property key="state" type="string">floating</property>
          <property key="width" type="double">5</property>
          <property key="height" type="double">5</property>
          <property key="showTitleBar" type="bool">false</property>
        </gz-gui>
      </plugin>
      <plugin filename="GzSceneManager" name="Scene Manager">
        <gz-gui>
          <property key="resizable" type="bool">false</property>
          <property key="width" type="double">5</property>
          <property key="height" type="double">5</property>
          <property key="state" type="string">floating</property>
          <property key="showTitleBar" type="bool">false</property>
        </gz-gui>
      </plugin>
      <plugin filename="InteractiveViewControl" name="Interactive view control">
        <gz-gui>
          <property key="resizable" type="bool">false</property>
          <property key="width" type="double">5</property>
          <property key="height" type="double">5</property>
          <property key="state" type="string">floating</property>
          <property key="showTitleBar" type="bool">false</property>
        </gz-gui>
      </plugin>
      <plugin filename="SelectEntities" name="Select Entities">
        <gz-gui>
          <anchors target="Select entities">
            <line own="right" target="right" />
            <line own="top" target="top" />
          </anchors>
          <property key="resizable" type="bool">false</property>
          <property key="width" type="double">5</property>
          <property key="height" type="double">5</property>
          <property key="state" type="string">floating</property>
          <property key="showTitleBar" type="bool">false</property>
        </gz-gui>
      </plugin>
      <plugin filename="VisualizationCapabilities" name="Visualization Capabilities">
        <gz-gui>
          <property key="resizable" type="bool">false</property>
          <property key="width" type="double">5</property>
          <property key="height" type="double">5</property>
          <property key="state" type="string">floating</property>
          <property key="showTitleBar" type="bool">false</property>
        </gz-gui>
      </plugin>
      <!-- Insert simple shapes -->
      <plugin filename="Shapes" name="Shapes">
        <gz-gui>
          <property key="resizable" type="bool">false</property>
          <property key="x" type="double">0</property>
          <property key="y" type="double">0</property>
          <property key="width" type="double">250</property>
          <property key="height" type="double">50</property>
          <property key="state" type="string">floating</property>
          <property key="showTitleBar" type="bool">false</property>
          <property key="cardBackground" type="string">#666666</property>
        </gz-gui>
      </plugin>

      <!-- Insert lights -->
      <plugin filename="Lights" name="Lights">
        <gz-gui>
          <property key="resizable" type="bool">false</property>
          <property key="x" type="double">250</property>
          <property key="y" type="double">0</property>
          <property key="width" type="double">150</property>
          <property key="height" type="double">50</property>
          <property key="state" type="string">floating</property>
          <property key="showTitleBar" type="bool">false</property>
          <property key="cardBackground" type="string">#666666</property>
        </gz-gui>
      </plugin>

      <!-- Translate / rotate -->
      <plugin filename="TransformControl" name="Transform control">
        <gz-gui>
          <property key="resizable" type="bool">false</property>
          <property key="x" type="double">0</property>
          <property key="y" type="double">50</property>
          <property key="width" type="double">250</property>
          <property key="height" type="double">50</property>
          <property key="state" type="string">floating</property>
          <property key="showTitleBar" type="bool">false</property>
          <property key="cardBackground" type="string">#777777</property>
        </gz-gui>
      </plugin>
      <!-- Screenshot -->
      <plugin filename="Screenshot" name="Screenshot">
        <gz-gui>
          <property key="resizable" type="bool">false</property>
          <property key="x" type="double">250</property>
          <property key="y" type="double">50</property>
          <property key="width" type="double">50</property>
          <property key="height" type="double">50</property>
          <property key="state" type="string">floating</property>
          <property key="showTitleBar" type="bool">false</property>
          <property key="cardBackground" type="string">#777777</property>
        </gz-gui>
      </plugin>
      <plugin filename="CameraTracking" name="Camera Tracking">
        <gz-gui>
          <property key="resizable" type="bool">false</property>
          <property key="width" type="double">5</property>
          <property key="height" type="double">5</property>
          <property key="state" type="string">floating</property>
          <property key="showTitleBar" type="bool">false</property>
        </gz-gui>
      </plugin>
      <!-- World control -->
      <plugin filename="WorldControl" name="World control">
        <gz-gui>
          <title>World control</title>
          <property type="bool" key="showTitleBar">false</property>
          <property type="bool" key="resizable">false</property>
          <property type="double" key="height">72</property>
          <property type="double" key="z">1</property>

          <property type="string" key="state">floating</property>
          <anchors target="3D View">
            <line own="left" target="left" />
            <line own="bottom" target="bottom" />
          </anchors>
        </gz-gui>

        <play_pause>true</play_pause>
        <step>true</step>
        <start_paused>true</start_paused>
        <use_event>true</use_event>

      </plugin>

      <!-- World statistics -->
      <plugin filename="WorldStats" name="World stats">
        <gz-gui>
          <title>World stats</title>
          <property type="bool" key="showTitleBar">false</property>
          <property type="bool" key="resizable">false</property>
          <property type="double" key="height">110</property>
          <property type="double" key="width">290</property>
          <property type="double" key="z">1</property>

          <property type="string" key="state">floating</property>
          <anchors target="3D View">
            <line own="right" target="right" />
            <line own="bottom" target="bottom" />
          </anchors>
        </gz-gui>

        <sim_time>true</sim_time>
        <real_time>true</real_time>
        <real_time_factor>true</real_time_factor>
        <iterations>true</iterations>
      </plugin>

      <!-- Video recorder -->
      <plugin filename="VideoRecorder" name="VideoRecorder">
        <gz-gui>
          <property key="resizable" type="bool">false</property>
          <property key="x" type="double">300</property>
          <property key="y" type="double">50</property>
          <property key="width" type="double">50</property>
          <property key="height" type="double">50</property>
          <property key="state" type="string">floating</property>
          <property key="showTitleBar" type="bool">false</property>
          <property key="cardBackground" type="string">#777777</property>
        </gz-gui>

        <record_video>
          <use_sim_time>true</use_sim_time>
          <lockstep>false</lockstep>
          <bitrate>4000000</bitrate>
        </record_video>
      </plugin>
    </gui>

    <gravity>0 0 -9.8000000000000007</gravity>
    <magnetic_field>5.5644999999999998e-06 2.2875799999999999e-05 -4.2388400000000002e-05</magnetic_field>
    <atmosphere type='adiabatic' />
    <physics type='ode'>
      <max_step_size>0.001</max_step_size>
      <real_time_factor>1</real_time_factor>
      <real_time_update_rate>1000</real_time_update_rate>
    </physics>
    <scene>
      <ambient>0.400000006 0.400000006 0.400000006 1</ambient>
      <background>0.699999988 0.699999988 0.699999988 1</background>
      <shadows>true</shadows>
    </scene>
    <model name='ground_plane'>
      <static>true</static>
      <link name='link'>
        <collision name='collision'>
          <geometry>
            <plane>
              <normal>0 0 1</normal>
              <size>1 1</size>
            </plane>
          </geometry>
          <surface>
            <friction>
              <ode />
            </friction>
            <bounce />
            <contact />
          </surface>
        </collision>
        <visual name='visual'>
          <geometry>
            <plane>
              <normal>0 0 1</normal>
              <size>100 100</size>
            </plane>
          </geometry>
          <material>
            <ambient>0.800000012 0.800000012 0.800000012 1</ambient>
            <diffuse>0.800000012 0.800000012 0.800000012 1</diffuse>
            <specular>0.800000012 0.800000012 0.800000012 1</specular>
          </material>
        </visual>
        <pose>0 0 0 0 0 0</pose>
        <inertial>
          <pose>0 0 0 0 0 0</pose>
          <mass>1</mass>
          <inertia>
            <ixx>1</ixx>
            <ixy>0</ixy>
            <ixz>0</ixz>
            <iyy>1</iyy>
            <iyz>0</iyz>
            <izz>1</izz>
          </inertia>
        </inertial>
        <enable_wind>false</enable_wind>
      </link>
      <pose>0 0 0 0 0 0</pose>
      <self_collide>false</self_collide>
    </model>
    <model name='h1_2'>
      <plugin name='gz::sim::systems::UnitreePlugin' filename='gz-unitree' />
      <plugin filename="gz-sim-imu-system"
        name="gz::sim::systems::Imu">
      </plugin>
      <self_collide>true</self_collide>
      <link name='pelvis'>
        <inertial>
          <pose>-0.00040000000000000002 3.6999999999999998e-05 -0.046864000000000003 0 0 0</pose>
          <mass>5.9829999999999997</mass>
          <inertia>
            <ixx>0.049168411000000002</ixx>
            <ixy>-1.9868999999999999e-05</ixy>
            <ixz>-4.846e-05</ixz>
            <iyy>0.0090258439999999999</iyy>
            <iyz>3.4309999999999998e-06</iyz>
            <izz>0.053155890999999997</izz>
          </inertia>
        </inertial>
        <collision name='pelvis_collision'>
          <pose>0 0 0 0 0 0</pose>
          <geometry>
            <sphere>
              <radius>0.050000000000000003</radius>
            </sphere>
          </geometry>
          <surface>
            <friction>
              <ode />
            </friction>
            <bounce />
            <contact />
          </surface>
        </collision>
        <visual name='pelvis_visual'>
          <pose>0 0 0 0 0 0</pose>
          <geometry>
            <mesh>
              <scale>1 1 1</scale>
              <uri>./h1_2_meshes/pelvis.STL</uri>
            </mesh>
          </geometry>
          <material>
            <diffuse>0.125 0.125 0.125 1</diffuse>
            <ambient>0.125 0.125 0.125 1</ambient>
          </material>
        </visual>
        <pose>0 0 0 0 0 0</pose>
        <enable_wind>false</enable_wind>
      </link>
      <joint name='left_hip_yaw_joint' type='revolute'>
        <pose>0 0 0 0 0 0</pose>
        <parent>pelvis</parent>
        <child>left_hip_yaw_link</child>
        <axis>
          <xyz>0 0 1</xyz>
          <limit>
            <lower>-0.42999999999999999</lower>
            <upper>0.42999999999999999</upper>
            <effort>200</effort>
            <velocity>23</velocity>
            <stiffness>100000000</stiffness>
            <dissipation>1</dissipation>
          </limit>
          <dynamics>
            <spring_reference>0</spring_reference>
            <spring_stiffness>0</spring_stiffness>
            <damping>0</damping>
            <friction>0</friction>
          </dynamics>
        </axis>
      </joint>
      <link name='left_hip_yaw_link'>
        <pose>0 0.087499999999999994 -0.16320000000000001 0 0 0</pose>
        <inertial>
          <pose>0 -0.026197000000000002 0.0066470000000000001 0 0 0</pose>
          <mass>2.8290000000000002</mass>
          <inertia>
            <ixx>0.0045536049999999996</ixx>
            <ixy>5.0000000000000001e-09</ixy>
            <ixz>8.1699999999999997e-07</ixz>
            <iyy>0.0056887300000000003</iyy>
            <iyz>-0.00034515700000000002</iyz>
            <izz>0.003548907</izz>
          </inertia>
        </inertial>
        <collision name='left_hip_yaw_link_collision'>
          <pose>0.02 0 0 0 1.5707963267948966 0</pose>
          <geometry>
            <cylinder>
              <length>0.02</length>
              <radius>0.01</radius>
            </cylinder>
          </geometry>
          <surface>
            <friction>
              <ode />
            </friction>
            <bounce />
            <contact />
          </surface>
        </collision>
        <visual name='left_hip_yaw_link_visual'>
          <pose>0 0 0 0 0 0</pose>
          <geometry>
            <mesh>
              <scale>1 1 1</scale>
              <uri>./h1_2_meshes/left_hip_yaw_link.STL</uri>
            </mesh>
          </geometry>
          <material>
            <diffuse>0.125 0.125 0.125 1</diffuse>
            <ambient>0.125 0.125 0.125 1</ambient>
          </material>
        </visual>
        <enable_wind>false</enable_wind>
      </link>
      <joint name='left_hip_pitch_joint' type='revolute'>
        <pose>0 0 0 0 0 0</pose>
        <parent>left_hip_yaw_link</parent>
        <child>left_hip_pitch_link</child>
        <axis>
          <xyz>0 1 0</xyz>
          <limit>
            <lower>-3.1400000000000001</lower>
            <upper>2.5</upper>
            <effort>200</effort>
            <velocity>23</velocity>
            <stiffness>100000000</stiffness>
            <dissipation>1</dissipation>
          </limit>
          <dynamics>
            <spring_reference>0</spring_reference>
            <spring_stiffness>0</spring_stiffness>
            <damping>0</damping>
            <friction>0</friction>
          </dynamics>
        </axis>
      </joint>
      <link name='left_hip_pitch_link'>
        <pose>0 0.16299999999999998 -0.16320000000000001 0 0 0</pose>
        <inertial>
          <pose>-0.0078100000000000001 -0.0047239999999999999 -6.3e-05 0 0 0</pose>
          <mass>2.9199999999999999</mass>
          <inertia>
            <ixx>0.0055947000000000002</ixx>
            <ixy>0.000143308</ixy>
            <ixz>-1.1847e-05</ixz>
            <iyy>0.0038625809999999999</iyy>
            <iyz>-9.6069999999999997e-06</iyz>
            <izz>0.0044505630000000003</izz>
          </inertia>
        </inertial>
        <collision name='left_hip_pitch_link_collision'>
          <pose>0 0 -0.20000000000000001 0 0 0</pose>
          <geometry>
            <cylinder>
              <length>0.20000000000000001</length>
              <radius>0.02</radius>
            </cylinder>
          </geometry>
          <surface>
            <friction>
              <ode />
            </friction>
            <bounce />
            <contact />
          </surface>
        </collision>
        <visual name='left_hip_pitch_link_visual'>
          <pose>0 0 0 0 0 0</pose>
          <geometry>
            <mesh>
              <scale>1 1 1</scale>
              <uri>
                ./h1_2_meshes/left_hip_pitch_link.STL</uri>
            </mesh>
          </geometry>
          <material>
            <diffuse>0.125 0.125 0.125 1</diffuse>
            <ambient>0.125 0.125 0.125 1</ambient>
          </material>
        </visual>
        <enable_wind>false</enable_wind>
      </link>
      <joint name='left_hip_roll_joint' type='revolute'>
        <pose>0 0 0 0 0 0</pose>
        <parent>left_hip_pitch_link</parent>
        <child>left_hip_roll_link</child>
        <axis>
          <xyz>1 0 0</xyz>
          <limit>
            <lower>-0.42999999999999999</lower>
            <upper>3.1400000000000001</upper>
            <effort>200</effort>
            <velocity>23</velocity>
            <stiffness>100000000</stiffness>
            <dissipation>1</dissipation>
          </limit>
          <dynamics>
            <spring_reference>0</spring_reference>
            <spring_stiffness>0</spring_stiffness>
            <damping>0</damping>
            <friction>0</friction>
          </dynamics>
        </axis>
      </joint>
      <link name='left_hip_roll_link'>
        <pose>0 0.16299999999999998 -0.16320000000000001 0 0 0</pose>
        <inertial>
          <pose>0.0041710000000000002 -0.0085760000000000003 -0.19450899999999999 0 0 0</pose>
          <mass>4.9619999999999997</mass>
          <inertia>
            <ixx>0.046305869</ixx>
            <ixy>-0.00032262600000000001</ixy>
            <ixz>-0.0011997030000000001</ixz>
            <iyy>0.047955402000000001</iyy>
            <iyz>0.00028814699999999999</iyz>
            <izz>0.0089145179999999997</izz>
          </inertia>
        </inertial>
        <collision name='left_hip_roll_link_collision'>
          <pose>0 0.059999999999999998 0 1.5707963267948959 0 0</pose>
          <geometry>
            <cylinder>
              <length>0.01</length>
              <radius>0.02</radius>
            </cylinder>
          </geometry>
          <surface>
            <friction>
              <ode />
            </friction>
            <bounce />
            <contact />
          </surface>
        </collision>
        <visual name='left_hip_roll_link_visual'>
          <pose>0 0 0 0 0 0</pose>
          <geometry>
            <mesh>
              <scale>1 1 1</scale>
              <uri>
                ./h1_2_meshes/left_hip_roll_link.STL</uri>
            </mesh>
          </geometry>
          <material>
            <diffuse>0.125 0.125 0.125 1</diffuse>
            <ambient>0.125 0.125 0.125 1</ambient>
          </material>
        </visual>
        <enable_wind>false</enable_wind>
      </link>
      <joint name='left_knee_joint' type='revolute'>
        <pose>0 0 0 0 0 0</pose>
        <parent>left_hip_roll_link</parent>
        <child>left_knee_link</child>
        <axis>
          <xyz>0 1 0</xyz>
          <limit>
            <lower>-0.12</lower>
            <upper>2.1899999999999999</upper>
            <effort>300</effort>
            <velocity>14</velocity>
            <stiffness>100000000</stiffness>
            <dissipation>1</dissipation>
          </limit>
          <dynamics>
            <spring_reference>0</spring_reference>
            <spring_stiffness>0</spring_stiffness>
            <damping>0</damping>
            <friction>0</friction>
          </dynamics>
        </axis>
      </joint>
      <link name='left_knee_link'>
        <pose>0 0.16299999999999998 -0.56320000000000003 0 0 0</pose>
        <inertial>
          <pose>0.00017899999999999999 0.000121 -0.168936 0 0 0</pose>
          <mass>3.839</mass>
          <inertia>
            <ixx>0.039002362999999998</ixx>
            <ixy>-7.2364e-05</ixy>
            <ixz>-0.00079450600000000005</ixz>
            <iyy>0.039042375999999997</iyy>
            <iyz>-1.8663000000000001e-05</iyz>
            <izz>0.0050298290000000004</izz>
          </inertia>
        </inertial>
        <collision name='left_knee_link_collision'>
          <pose>0 0 -0.20000000000000001 0 0 0</pose>
          <geometry>
            <cylinder>
              <length>0.20000000000000001</length>
              <radius>0.02</radius>
            </cylinder>
          </geometry>
          <surface>
            <friction>
              <ode />
            </friction>
            <bounce />
            <contact />
          </surface>
        </collision>
        <visual name='left_knee_link_visual'>
          <pose>0 0 0 0 0 0</pose>
          <geometry>
            <mesh>
              <scale>1 1 1</scale>
              <uri>./h1_2_meshes/left_knee_link.STL</uri>
            </mesh>
          </geometry>
          <material>
            <diffuse>0.125 0.125 0.125 1</diffuse>
            <ambient>0.125 0.125 0.125 1</ambient>
          </material>
        </visual>
        <enable_wind>false</enable_wind>
      </link>
      <joint name='left_ankle_pitch_joint' type='revolute'>
        <pose>0 0 0 0 0 0</pose>
        <parent>left_knee_link</parent>
        <child>left_ankle_pitch_link</child>
        <axis>
          <xyz>0 1 0</xyz>
          <limit>
            <lower>-0.89733399999999996</lower>
            <upper>0.52359800000000001</upper>
            <effort>60</effort>
            <velocity>9</velocity>
            <stiffness>100000000</stiffness>
            <dissipation>1</dissipation>
          </limit>
          <dynamics>
            <spring_reference>0</spring_reference>
            <spring_stiffness>0</spring_stiffness>
            <damping>0</damping>
            <friction>0</friction>
          </dynamics>
        </axis>
      </joint>
      <link name='left_ankle_pitch_link'>
        <pose>0 0.16299999999999998 -0.96320000000000006 0 0 0</pose>
        <inertial>
          <pose>-0.00029399999999999999 0 -0.010794 0 0 0</pose>
          <mass>0.10199999999999999</mass>
          <inertia>
            <ixx>2.3944e-05</ixx>
            <ixy>0</ixy>
            <ixz>1.2100000000000001e-07</ixz>
            <iyy>2.1837000000000001e-05</iyy>
            <iyz>0</iyz>
            <izz>1.3414000000000001e-05</izz>
          </inertia>
        </inertial>
        <collision name='left_ankle_pitch_link_collision'>
          <pose>0 0 0 0 0 0</pose>
          <geometry>
            <mesh>
              <scale>1 1 1</scale>
              <uri>
                ./h1_2_meshes/left_ankle_pitch_link.STL</uri>
            </mesh>
          </geometry>
        </collision>
        <visual name='left_ankle_pitch_link_visual'>
          <pose>0 0 0 0 0 0</pose>
          <geometry>
            <mesh>
              <scale>1 1 1</scale>
              <uri>
                ./h1_2_meshes/left_ankle_pitch_link.STL</uri>
            </mesh>
          </geometry>
          <material>
            <diffuse>0.125 0.125 0.125 1</diffuse>
            <ambient>0.125 0.125 0.125 1</ambient>
          </material>
        </visual>
        <enable_wind>false</enable_wind>
      </link>
      <joint name='left_ankle_roll_joint' type='revolute'>
        <pose>0 0 0 0 0 0</pose>
        <parent>left_ankle_pitch_link</parent>
        <child>left_ankle_roll_link</child>
        <axis>
          <xyz>1 0 0</xyz>
          <limit>
            <lower>-0.261799</lower>
            <upper>0.261799</upper>
            <effort>40</effort>
            <velocity>9</velocity>
            <stiffness>100000000</stiffness>
            <dissipation>1</dissipation>
          </limit>
          <dynamics>
            <spring_reference>0</spring_reference>
            <spring_stiffness>0</spring_stiffness>
            <damping>0</damping>
            <friction>0</friction>
          </dynamics>
        </axis>
      </joint>
      <link name='left_ankle_roll_link'>
        <pose>0 0.16299999999999998 -0.98320000000000007 0 0 0</pose>
        <inertial>
          <pose>0.029589000000000001 0 -0.015973000000000001 0 0 0</pose>
          <mass>0.747</mass>
          <inertia>
            <ixx>0.00064882999999999998</ixx>
            <ixy>0</ixy>
            <ixz>0.00015838000000000001</ixz>
            <iyy>0.0034353389999999999</iyy>
            <iyz>0</iyz>
            <izz>0.0035832590000000001</izz>
          </inertia>
        </inertial>
        <collision name='left_ankle_roll_link_collision'>
          <pose>0 0 0 0 0 0</pose>
          <geometry>
            <mesh>
              <scale>1 1 1</scale>
              <uri>
                ./h1_2_meshes/left_ankle_roll_link.STL</uri>
            </mesh>
          </geometry>
        </collision>
        <visual name='left_ankle_roll_link_visual'>
          <pose>0 0 0 0 0 0</pose>
          <geometry>
            <mesh>
              <scale>1 1 1</scale>
              <uri>
                ./h1_2_meshes/left_ankle_roll_link.STL</uri>
            </mesh>
          </geometry>
          <material>
            <diffuse>0.125 0.125 0.125 1</diffuse>
            <ambient>0.125 0.125 0.125 1</ambient>
          </material>
        </visual>
        <enable_wind>false</enable_wind>
      </link>
      <joint name='right_hip_yaw_joint' type='revolute'>
        <pose>0 0 0 0 0 0</pose>
        <parent>pelvis</parent>
        <child>right_hip_yaw_link</child>
        <axis>
          <xyz>0 0 1</xyz>
          <limit>
            <lower>-0.42999999999999999</lower>
            <upper>0.42999999999999999</upper>
            <effort>200</effort>
            <velocity>23</velocity>
            <stiffness>100000000</stiffness>
            <dissipation>1</dissipation>
          </limit>
          <dynamics>
            <spring_reference>0</spring_reference>
            <spring_stiffness>0</spring_stiffness>
            <damping>0</damping>
            <friction>0</friction>
          </dynamics>
        </axis>
      </joint>
      <link name='right_hip_yaw_link'>
        <pose>0 -0.087499999999999994 -0.16320000000000001 0 0 0</pose>
        <inertial>
          <pose>0 0.026197000000000002 0.0066470000000000001 0 0 0</pose>
          <mass>2.8290000000000002</mass>
          <inertia>
            <ixx>0.0045536049999999996</ixx>
            <ixy>-5.0000000000000001e-09</ixy>
            <ixz>8.1699999999999997e-07</ixz>
            <iyy>0.0056887300000000003</iyy>
            <iyz>0.00034515700000000002</iyz>
            <izz>0.003548907</izz>
          </inertia>
        </inertial>
        <collision name='right_hip_yaw_link_collision'>
          <pose>0.02 0 0 0 1.5707963267948966 0</pose>
          <geometry>
            <cylinder>
              <length>0.02</length>
              <radius>0.01</radius>
            </cylinder>
          </geometry>
          <surface>
            <friction>
              <ode />
            </friction>
            <bounce />
            <contact />
          </surface>
        </collision>
        <visual name='right_hip_yaw_link_visual'>
          <pose>0 0 0 0 0 0</pose>
          <geometry>
            <mesh>
              <scale>1 1 1</scale>
              <uri>
                ./h1_2_meshes/right_hip_yaw_link.STL</uri>
            </mesh>
          </geometry>
          <material>
            <diffuse>0.125 0.125 0.125 1</diffuse>
            <ambient>0.125 0.125 0.125 1</ambient>
          </material>
        </visual>
        <enable_wind>false</enable_wind>
      </link>
      <joint name='right_hip_pitch_joint' type='revolute'>
        <pose>0 0 0 0 0 0</pose>
        <parent>right_hip_yaw_link</parent>
        <child>right_hip_pitch_link</child>
        <axis>
          <xyz>0 1 0</xyz>
          <limit>
            <lower>-3.1400000000000001</lower>
            <upper>2.5</upper>
            <effort>200</effort>
            <velocity>23</velocity>
            <stiffness>100000000</stiffness>
            <dissipation>1</dissipation>
          </limit>
          <dynamics>
            <spring_reference>0</spring_reference>
            <spring_stiffness>0</spring_stiffness>
            <damping>0</damping>
            <friction>0</friction>
          </dynamics>
        </axis>
      </joint>
      <link name='right_hip_pitch_link'>
        <pose>0 -0.16299999999999998 -0.16320000000000001 0 0 0</pose>
        <inertial>
          <pose>-0.0078100000000000001 0.0047239999999999999 -6.3e-05 0 0 0</pose>
          <mass>2.9199999999999999</mass>
          <inertia>
            <ixx>0.0055947000000000002</ixx>
            <ixy>-0.000143308</ixy>
            <ixz>-1.1847e-05</ixz>
            <iyy>0.0038625809999999999</iyy>
            <iyz>9.6069999999999997e-06</iyz>
            <izz>0.0044505630000000003</izz>
          </inertia>
        </inertial>
        <collision name='right_hip_pitch_link_collision'>
          <pose>0 0 -0.20000000000000001 0 0 0</pose>
          <geometry>
            <cylinder>
              <length>0.20000000000000001</length>
              <radius>0.02</radius>
            </cylinder>
          </geometry>
          <surface>
            <friction>
              <ode />
            </friction>
            <bounce />
            <contact />
          </surface>
        </collision>
        <visual name='right_hip_pitch_link_visual'>
          <pose>0 0 0 0 0 0</pose>
          <geometry>
            <mesh>
              <scale>1 1 1</scale>
              <uri>
                ./h1_2_meshes/right_hip_pitch_link.STL</uri>
            </mesh>
          </geometry>
          <material>
            <diffuse>0.125 0.125 0.125 1</diffuse>
            <ambient>0.125 0.125 0.125 1</ambient>
          </material>
        </visual>
        <enable_wind>false</enable_wind>
      </link>
      <joint name='right_hip_roll_joint' type='revolute'>
        <pose>0 0 0 0 0 0</pose>
        <parent>right_hip_pitch_link</parent>
        <child>right_hip_roll_link</child>
        <axis>
          <xyz>1 0 0</xyz>
          <limit>
            <lower>-3.1400000000000001</lower>
            <upper>0.42999999999999999</upper>
            <effort>200</effort>
            <velocity>23</velocity>
            <stiffness>100000000</stiffness>
            <dissipation>1</dissipation>
          </limit>
          <dynamics>
            <spring_reference>0</spring_reference>
            <spring_stiffness>0</spring_stiffness>
            <damping>0</damping>
            <friction>0</friction>
          </dynamics>
        </axis>
      </joint>
      <link name='right_hip_roll_link'>
        <pose>0 -0.16299999999999998 -0.16320000000000001 0 0 0</pose>
        <inertial>
          <pose>0.0041710000000000002 0.0085760000000000003 -0.19450899999999999 0 0 0</pose>
          <mass>4.9619999999999997</mass>
          <inertia>
            <ixx>0.046305869</ixx>
            <ixy>0.00032262600000000001</ixy>
            <ixz>-0.0011997030000000001</ixz>
            <iyy>0.047955402000000001</iyy>
            <iyz>-0.00028814699999999999</iyz>
            <izz>0.0089145179999999997</izz>
          </inertia>
        </inertial>
        <collision name='right_hip_roll_link_collision'>
          <pose>0 -0.059999999999999998 0 1.5707963267948959 0 0</pose>
          <geometry>
            <cylinder>
              <length>0.01</length>
              <radius>0.02</radius>
            </cylinder>
          </geometry>
          <surface>
            <friction>
              <ode />
            </friction>
            <bounce />
            <contact />
          </surface>
        </collision>
        <visual name='right_hip_roll_link_visual'>
          <pose>0 0 0 0 0 0</pose>
          <geometry>
            <mesh>
              <scale>1 1 1</scale>
              <uri>
                ./h1_2_meshes/right_hip_roll_link.STL</uri>
            </mesh>
          </geometry>
          <material>
            <diffuse>0.125 0.125 0.125 1</diffuse>
            <ambient>0.125 0.125 0.125 1</ambient>
          </material>
        </visual>
        <enable_wind>false</enable_wind>
      </link>
      <joint name='right_knee_joint' type='revolute'>
        <pose>0 0 0 0 0 0</pose>
        <parent>right_hip_roll_link</parent>
        <child>right_knee_link</child>
        <axis>
          <xyz>0 1 0</xyz>
          <limit>
            <lower>-0.12</lower>
            <upper>2.1899999999999999</upper>
            <effort>300</effort>
            <velocity>14</velocity>
            <stiffness>100000000</stiffness>
            <dissipation>1</dissipation>
          </limit>
          <dynamics>
            <spring_reference>0</spring_reference>
            <spring_stiffness>0</spring_stiffness>
            <damping>0</damping>
            <friction>0</friction>
          </dynamics>
        </axis>
      </joint>
      <link name='right_knee_link'>
        <pose>0 -0.16299999999999998 -0.56320000000000003 0 0 0</pose>
        <inertial>
          <pose>0.00017899999999999999 -0.000121 -0.168936 0 0 0</pose>
          <mass>3.839</mass>
          <inertia>
            <ixx>0.039002362999999998</ixx>
            <ixy>7.2364e-05</ixy>
            <ixz>-0.00079450600000000005</ixz>
            <iyy>0.039042375999999997</iyy>
            <iyz>1.8663000000000001e-05</iyz>
            <izz>0.0050298290000000004</izz>
          </inertia>
        </inertial>
        <collision name='right_knee_link_collision'>
          <pose>0 0 -0.20000000000000001 0 0 0</pose>
          <geometry>
            <cylinder>
              <length>0.20000000000000001</length>
              <radius>0.02</radius>
            </cylinder>
          </geometry>
          <surface>
            <friction>
              <ode />
            </friction>
            <bounce />
            <contact />
          </surface>
        </collision>
        <visual name='right_knee_link_visual'>
          <pose>0 0 0 0 0 0</pose>
          <geometry>
            <mesh>
              <scale>1 1 1</scale>
              <uri>./h1_2_meshes/right_knee_link.STL</uri>
            </mesh>
          </geometry>
          <material>
            <diffuse>0.125 0.125 0.125 1</diffuse>
            <ambient>0.125 0.125 0.125 1</ambient>
          </material>
        </visual>
        <enable_wind>false</enable_wind>
      </link>
      <joint name='right_ankle_pitch_joint' type='revolute'>
        <pose>0 0 0 0 0 0</pose>
        <parent>right_knee_link</parent>
        <child>right_ankle_pitch_link</child>
        <axis>
          <xyz>0 1 0</xyz>
          <limit>
            <lower>-0.89733399999999996</lower>
            <upper>0.52359800000000001</upper>
            <effort>60</effort>
            <velocity>9</velocity>
            <stiffness>100000000</stiffness>
            <dissipation>1</dissipation>
          </limit>
          <dynamics>
            <spring_reference>0</spring_reference>
            <spring_stiffness>0</spring_stiffness>
            <damping>0</damping>
            <friction>0</friction>
          </dynamics>
        </axis>
      </joint>
      <link name='right_ankle_pitch_link'>
        <pose>0 -0.16299999999999998 -0.96320000000000006 0 0 0</pose>
        <inertial>
          <pose>-0.00029399999999999999 0 -0.010794 0 0 0</pose>
          <mass>0.10199999999999999</mass>
          <inertia>
            <ixx>2.3944e-05</ixx>
            <ixy>0</ixy>
            <ixz>1.2100000000000001e-07</ixz>
            <iyy>2.1837000000000001e-05</iyy>
            <iyz>0</iyz>
            <izz>1.3414000000000001e-05</izz>
          </inertia>
        </inertial>
        <collision name='right_ankle_pitch_link_collision'>
          <pose>0 0 0 0 0 0</pose>
          <geometry>
            <mesh>
              <scale>1 1 1</scale>
              <uri>
                ./h1_2_meshes/right_ankle_pitch_link.STL</uri>
            </mesh>
          </geometry>
        </collision>
        <visual name='right_ankle_pitch_link_visual'>
          <pose>0 0 0 0 0 0</pose>
          <geometry>
            <mesh>
              <scale>1 1 1</scale>
              <uri>
                ./h1_2_meshes/right_ankle_pitch_link.STL</uri>
            </mesh>
          </geometry>
          <material>
            <diffuse>0.125 0.125 0.125 1</diffuse>
            <ambient>0.125 0.125 0.125 1</ambient>
          </material>
        </visual>
        <enable_wind>false</enable_wind>
      </link>
      <joint name='right_ankle_roll_joint' type='revolute'>
        <pose>0 0 0 0 0 0</pose>
        <parent>right_ankle_pitch_link</parent>
        <child>right_ankle_roll_link</child>
        <axis>
          <xyz>1 0 0</xyz>
          <limit>
            <lower>-0.261799</lower>
            <upper>0.261799</upper>
            <effort>40</effort>
            <velocity>9</velocity>
            <stiffness>100000000</stiffness>
            <dissipation>1</dissipation>
          </limit>
          <dynamics>
            <spring_reference>0</spring_reference>
            <spring_stiffness>0</spring_stiffness>
            <damping>0</damping>
            <friction>0</friction>
          </dynamics>
        </axis>
      </joint>
      <link name='right_ankle_roll_link'>
        <pose>0 -0.16299999999999998 -0.98320000000000007 0 0 0</pose>
        <inertial>
          <pose>0.029589000000000001 0 -0.015973000000000001 0 0 0</pose>
          <mass>0.747</mass>
          <inertia>
            <ixx>0.00064882999999999998</ixx>
            <ixy>0</ixy>
            <ixz>0.00015838000000000001</ixz>
            <iyy>0.0034353389999999999</iyy>
            <iyz>0</iyz>
            <izz>0.0035832590000000001</izz>
          </inertia>
        </inertial>
        <collision name='right_ankle_roll_link_collision'>
          <pose>0 0 0 0 0 0</pose>
          <geometry>
            <mesh>
              <scale>1 1 1</scale>
              <uri>
                ./h1_2_meshes/right_ankle_roll_link.STL</uri>
            </mesh>
          </geometry>
        </collision>
        <visual name='right_ankle_roll_link_visual'>
          <pose>0 0 0 0 0 0</pose>
          <geometry>
            <mesh>
              <scale>1 1 1</scale>
              <uri>
                ./h1_2_meshes/right_ankle_roll_link.STL</uri>
            </mesh>
          </geometry>
          <material>
            <diffuse>0.125 0.125 0.125 1</diffuse>
            <ambient>0.125 0.125 0.125 1</ambient>
          </material>
        </visual>
        <enable_wind>false</enable_wind>
      </link>
      <joint name='torso_joint' type='revolute'>
        <pose>0 0 0 0 0 0</pose>
        <parent>pelvis</parent>
        <child>torso_link</child>
        <axis>
          <xyz>0 0 1</xyz>
          <limit>
            <lower>-2.3500000000000001</lower>
            <upper>2.3500000000000001</upper>
            <effort>200</effort>
            <velocity>23</velocity>
            <stiffness>100000000</stiffness>
            <dissipation>1</dissipation>
          </limit>
          <dynamics>
            <spring_reference>0</spring_reference>
            <spring_stiffness>0</spring_stiffness>
            <damping>0</damping>
            <friction>0</friction>
          </dynamics>
        </axis>
      </joint>
      <link name='torso_link'>
        <sensor name="imu_sensor" type="imu">
          <always_on>1</always_on>
          <update_rate>200</update_rate>
          <visualize>true</visualize>
          <topic>imu</topic>
        </sensor>
        <pose>0 0 0 0 0 0</pose>
        <inertial>
          <pose>0.00048899999999999996 0.002797 0.20483999999999999 0 0 0</pose>
          <mass>17.789000000000001</mass>
          <inertia>
            <ixx>0.48730000000000001</ixx>
            <ixy>-0.00053762999999999999</ixy>
            <ixz>0.0020276000000000001</ixz>
            <iyy>0.40962999999999999</iyy>
            <iyz>-0.00074582000000000001</iyz>
            <izz>0.12784999999999999</izz>
          </inertia>
        </inertial>
        <collision name='torso_link_collision'>
          <pose>0 0 0.14999999999999999 0 0 0</pose>
          <geometry>
            <box>
              <size>0.080000000000000002 0.16 0.10000000000000001</size>
            </box>
          </geometry>
          <surface>
            <friction>
              <ode />
            </friction>
            <bounce />
            <contact />
          </surface>
        </collision>
        <visual name='torso_link_visual'>
          <pose>0 0 0 0 0 0</pose>
          <geometry>
            <mesh>
              <scale>1 1 1</scale>
              <uri>./h1_2_meshes/torso_link.STL</uri>
            </mesh>
          </geometry>
          <material>
            <diffuse>0.125 0.125 0.125 1</diffuse>
            <ambient>0.125 0.125 0.125 1</ambient>
          </material>
        </visual>
        <visual name='torso_link_fixed_joint_lump__logo_link_visual_1'>
          <pose>0 0 0 0 0 0</pose>
          <geometry>
            <mesh>
              <scale>1 1 1</scale>
              <uri>./h1_2_meshes/logo_link.STL</uri>
            </mesh>
          </geometry>
          <material>
            <diffuse>1 1 1 1</diffuse>
            <ambient>1 1 1 1</ambient>
          </material>
        </visual>
        <enable_wind>false</enable_wind>
      </link>
      <joint name='left_shoulder_pitch_joint' type='revolute'>
        <pose>0 0 -5.5511151231257827e-17 0 0 0</pose>
        <parent>torso_link</parent>
        <child>left_shoulder_pitch_link</child>
        <axis>
          <xyz>0 1 0</xyz>
          <limit>
            <lower>-3.1400000000000001</lower>
            <upper>1.5700000000000001</upper>
            <effort>40</effort>
            <velocity>9</velocity>
            <stiffness>100000000</stiffness>
            <dissipation>1</dissipation>
          </limit>
          <dynamics>
            <spring_reference>0</spring_reference>
            <spring_stiffness>0</spring_stiffness>
            <damping>0</damping>
            <friction>0</friction>
          </dynamics>
        </axis>
      </joint>
      <link name='left_shoulder_pitch_link'>
        <pose>0 0.14806 0.42332999999999998 0.2618000000000002 0 0</pose>
        <inertial>
          <pose>0.0030530000000000002 0.060420000000000001 -0.0058999999999999999 0 0 0</pose>
          <mass>1.327</mass>
          <inertia>
            <ixx>0.00058661</ixx>
            <ixy>-2.0157e-05</ixy>
            <ixz>2.9849999999999998e-06</ixz>
            <iyy>0.00039889999999999999</iyy>
            <iyz>2.2379999999999999e-05</iyz>
            <izz>0.00052935999999999999</izz>
          </inertia>
        </inertial>
        <collision name='left_shoulder_pitch_link_collision'>
          <pose>0 0 0 0 0 0</pose>
          <geometry>
            <mesh>
              <scale>1 1 1</scale>
              <uri>
                ./h1_2_meshes/left_shoulder_pitch_link.STL</uri>
            </mesh>
          </geometry>
        </collision>
        <visual name='left_shoulder_pitch_link_visual'>
          <pose>0 0 0 0 0 0</pose>
          <geometry>
            <mesh>
              <scale>1 1 1</scale>
              <uri>
                ./h1_2_meshes/left_shoulder_pitch_link.STL</uri>
            </mesh>
          </geometry>
          <material>
            <diffuse>0.125 0.125 0.125 1</diffuse>
            <ambient>0.125 0.125 0.125 1</ambient>
          </material>
        </visual>
        <enable_wind>false</enable_wind>
      </link>
      <joint name='left_shoulder_roll_joint' type='revolute'>
        <pose>0 0 0 0 0 0</pose>
        <parent>left_shoulder_pitch_link</parent>
        <child>left_shoulder_roll_link</child>
        <axis>
          <xyz>1 0 0</xyz>
          <limit>
            <lower>-0.38</lower>
            <upper>3.3999999999999999</upper>
            <effort>40</effort>
            <velocity>9</velocity>
            <stiffness>100000000</stiffness>
            <dissipation>1</dissipation>
          </limit>
          <dynamics>
            <spring_reference>0</spring_reference>
            <spring_stiffness>0</spring_stiffness>
            <damping>0</damping>
            <friction>0</friction>
          </dynamics>
        </axis>
      </joint>
      <link name='left_shoulder_roll_link'>
        <pose>0.034200000000000001 0.20949962800064897 0.4335799421145623 0 0 0</pose>
        <inertial>
          <pose>-0.030932000000000001 -9.9999999999999995e-07 -0.10609 0 0 0</pose>
          <mass>1.393</mass>
          <inertia>
            <ixx>0.0018408000000000001</ixx>
            <ixy>3.9799999999999999e-07</ixy>
            <ixz>-0.00048324000000000002</ixz>
            <iyy>0.001934638</iyy>
            <iyz>1.61e-07</iyz>
            <izz>0.00061773299999999998</izz>
          </inertia>
        </inertial>
        <collision name='left_shoulder_roll_link_collision'>
          <pose>0 0 0 0 0 0</pose>
          <geometry>
            <mesh>
              <scale>1 1 1</scale>
              <uri>
                ./h1_2_meshes/left_shoulder_roll_link.STL</uri>
            </mesh>
          </geometry>
        </collision>
        <visual name='left_shoulder_roll_link_visual'>
          <pose>0 0 0 0 0 0</pose>
          <geometry>
            <mesh>
              <scale>1 1 1</scale>
              <uri>
                ./h1_2_meshes/left_shoulder_roll_link.STL</uri>
            </mesh>
          </geometry>
          <material>
            <diffuse>0.125 0.125 0.125 1</diffuse>
            <ambient>0.125 0.125 0.125 1</ambient>
          </material>
        </visual>
        <enable_wind>false</enable_wind>
      </link>
      <joint name='left_shoulder_yaw_joint' type='revolute'>
        <pose>0 0 0 0 0 0</pose>
        <parent>left_shoulder_roll_link</parent>
        <child>left_shoulder_yaw_link</child>
        <axis>
          <xyz>0 0 1</xyz>
          <limit>
            <lower>-2.6600000000000001</lower>
            <upper>3.0099999999999998</upper>
            <effort>18</effort>
            <velocity>20</velocity>
            <stiffness>100000000</stiffness>
            <dissipation>1</dissipation>
          </limit>
          <dynamics>
            <spring_reference>0</spring_reference>
            <spring_stiffness>0</spring_stiffness>
            <damping>0</damping>
            <friction>0</friction>
          </dynamics>
        </axis>
      </joint>
      <link name='left_shoulder_yaw_link'>
        <pose>0 0.20949962800064892 0.28797994211456235 0 0 0</pose>
        <inertial>
          <pose>0.0045830000000000003 0.0011280000000000001 -0.0011280000000000001 0 0 0</pose>
          <mass>1.5049999999999999</mass>
          <inertia>
            <ixx>0.0041989999999999996</ixx>
            <ixy>-1.7785999999999999e-05</ixy>
            <ixz>0.00018372000000000001</ixz>
            <iyy>0.0043138999999999999</iyy>
            <iyz>9.2780000000000003e-05</iyz>
            <izz>0.00065755000000000002</izz>
          </inertia>
        </inertial>
        <collision name='left_shoulder_yaw_link_collision'>
          <pose>0 0 0 0 0 0</pose>
          <geometry>
            <mesh>
              <scale>1 1 1</scale>
              <uri>
                ./h1_2_meshes/left_shoulder_yaw_link.STL</uri>
            </mesh>
          </geometry>
        </collision>
        <visual name='left_shoulder_yaw_link_visual'>
          <pose>0 0 0 0 0 0</pose>
          <geometry>
            <mesh>
              <scale>1 1 1</scale>
              <uri>
                ./h1_2_meshes/left_shoulder_yaw_link.STL</uri>
            </mesh>
          </geometry>
          <material>
            <diffuse>0.125 0.125 0.125 1</diffuse>
            <ambient>0.125 0.125 0.125 1</ambient>
          </material>
        </visual>
        <enable_wind>false</enable_wind>
      </link>
      <joint name='left_elbow_joint' type='revolute'>
        <pose>0 0 0 0 0 0</pose>
        <parent>left_shoulder_yaw_link</parent>
        <child>left_elbow_link</child>
        <axis>
          <xyz>0 1 0</xyz>
          <limit>
            <lower>-0.94999999999999996</lower>
            <upper>3.1800000000000002</upper>
            <effort>18</effort>
            <velocity>20</velocity>
            <stiffness>100000000</stiffness>
            <dissipation>1</dissipation>
          </limit>
          <dynamics>
            <spring_reference>0</spring_reference>
            <spring_stiffness>0</spring_stiffness>
            <damping>0</damping>
            <friction>0</friction>
          </dynamics>
        </axis>
      </joint>
      <link name='left_elbow_link'>
        <pose>0.0059999999999999967 0.2423996280006489 0.10597994211456241 0 0 0</pose>
        <inertial>
          <pose>0.077091999999999994 -0.028750999999999999 -0.0097140000000000004 0 0 0</pose>
          <mass>0.69099999999999995</mass>
          <inertia>
            <ixx>0.00031849100000000001</ixx>
            <ixy>0.00022455399999999999</ixy>
            <ixz>6.6207599999999999e-05</ixz>
            <iyy>0.00086122399999999995</iyy>
            <iyz>-2.3329e-05</iyz>
            <izz>0.00089789899999999996</izz>
          </inertia>
        </inertial>
        <collision name='left_elbow_link_collision'>
          <pose>0 0 0 0 0 0</pose>
          <geometry>
            <mesh>
              <scale>1 1 1</scale>
              <uri>./h1_2_meshes/left_elbow_link.STL</uri>
            </mesh>
          </geometry>
        </collision>
        <visual name='left_elbow_link_visual'>
          <pose>0 0 0 0 0 0</pose>
          <geometry>
            <mesh>
              <scale>1 1 1</scale>
              <uri>./h1_2_meshes/left_elbow_link.STL</uri>
            </mesh>
          </geometry>
          <material>
            <diffuse>0.125 0.125 0.125 1</diffuse>
            <ambient>0.125 0.125 0.125 1</ambient>
          </material>
        </visual>
        <enable_wind>false</enable_wind>
      </link>
      <joint name='left_wrist_roll_joint' type='revolute'>
        <pose>0 0 0 0 0 0</pose>
        <parent>left_elbow_link</parent>
        <child>left_wrist_roll_link</child>
        <axis>
          <xyz>1 0 0</xyz>
          <limit>
            <lower>-3.0099999999999998</lower>
            <upper>2.75</upper>
            <effort>19</effort>
            <velocity>31.399999999999999</velocity>
            <stiffness>100000000</stiffness>
            <dissipation>1</dissipation>
          </limit>
          <dynamics>
            <spring_reference>0</spring_reference>
            <spring_stiffness>0</spring_stiffness>
            <damping>0</damping>
            <friction>0</friction>
          </dynamics>
        </axis>
      </joint>
      <link name='left_wrist_roll_link'>
        <pose>0.127 0.20949962800064889 0.09497994211456251 0 0 0</pose>
        <inertial>
          <pose>0.035281 -0.00232 0.00033700000000000001 0 0 0</pose>
          <mass>0.68300000000000005</mass>
          <inertia>
            <ixx>0.00031327500000000001</ixx>
            <ixy>1.6521e-05</ixy>
            <ixz>-2.5009999999999999e-06</ixz>
            <iyy>0.00031041199999999998</iyy>
            <iyz>5.4349999999999996e-06</iyz>
            <izz>0.00034599799999999998</izz>
          </inertia>
        </inertial>
        <collision name='left_wrist_roll_link_collision'>
          <pose>0 0 0 0 0 0</pose>
          <geometry>
            <mesh>
              <scale>1 1 1</scale>
              <uri>
                ./h1_2_meshes/left_wrist_roll_link.STL</uri>
            </mesh>
          </geometry>
        </collision>
        <visual name='left_wrist_roll_link_visual'>
          <pose>0 0 0 0 0 0</pose>
          <geometry>
            <mesh>
              <scale>1 1 1</scale>
              <uri>
                ./h1_2_meshes/left_wrist_roll_link.STL</uri>
            </mesh>
          </geometry>
          <material>
            <diffuse>0.125 0.125 0.125 1</diffuse>
            <ambient>0.125 0.125 0.125 1</ambient>
          </material>
        </visual>
        <enable_wind>false</enable_wind>
      </link>
      <joint name='left_wrist_pitch_joint' type='revolute'>
        <pose>0 0 0 0 0 0</pose>
        <parent>left_wrist_roll_link</parent>
        <child>left_wrist_pitch_link</child>
        <axis>
          <xyz>0 1 0</xyz>
          <limit>
            <lower>-0.46250000000000002</lower>
            <upper>0.46250000000000002</upper>
            <effort>19</effort>
            <velocity>31.399999999999999</velocity>
            <stiffness>100000000</stiffness>
            <dissipation>1</dissipation>
          </limit>
          <dynamics>
            <spring_reference>0</spring_reference>
            <spring_stiffness>0</spring_stiffness>
            <damping>0</damping>
            <friction>0</friction>
          </dynamics>
        </axis>
      </joint>
      <link name='left_wrist_pitch_link'>
        <pose>0.214 0.20949962800064889 0.09497994211456251 0 0 0</pose>
        <inertial>
          <pose>0.020395 3.6000000000000001e-05 -0.0029729999999999999 0 0 0</pose>
          <mass>0.48399999999999999</mass>
          <inertia>
            <ixx>7.1364000000000003e-05</ixx>
            <ixy>3.0800000000000001e-07</ixy>
            <ixz>1.485e-06</ixz>
            <iyy>6.9914999999999997e-05</iyy>
            <iyz>-8.7999999999999994e-08</iyz>
            <izz>7.0702000000000002e-05</izz>
          </inertia>
        </inertial>
        <collision name='left_wrist_pitch_link_collision'>
          <pose>0 0 0 0 0 0</pose>
          <geometry>
            <mesh>
              <scale>1 1 1</scale>
              <uri>
                ./h1_2_meshes/left_wrist_pitch_link.STL</uri>
            </mesh>
          </geometry>
        </collision>
        <visual name='left_wrist_pitch_link_visual'>
          <pose>0 0 0 0 0 0</pose>
          <geometry>
            <mesh>
              <scale>1 1 1</scale>
              <uri>
                ./h1_2_meshes/left_wrist_pitch_link.STL</uri>
            </mesh>
          </geometry>
          <material>
            <diffuse>0.125 0.125 0.125 1</diffuse>
            <ambient>0.125 0.125 0.125 1</ambient>
          </material>
        </visual>
        <enable_wind>false</enable_wind>
      </link>
      <joint name='left_wrist_yaw_joint' type='revolute'>
        <pose>0 0 0 0 0 0</pose>
        <parent>left_wrist_pitch_link</parent>
        <child>left_wrist_yaw_link</child>
        <axis>
          <xyz>0 0 1</xyz>
          <limit>
            <lower>-1.27</lower>
            <upper>1.27</upper>
            <effort>19</effort>
            <velocity>31.399999999999999</velocity>
            <stiffness>100000000</stiffness>
            <dissipation>1</dissipation>
          </limit>
          <dynamics>
            <spring_reference>0</spring_reference>
            <spring_stiffness>0</spring_stiffness>
            <damping>0</damping>
            <friction>0</friction>
          </dynamics>
        </axis>
      </joint>
      <link name='left_wrist_yaw_link'>
        <pose>0.23399999999999996 0.20949962800064889 0.09497994211456251 0 0 0</pose>
        <inertial>
          <pose>0.077030310100591484 -0.0013144103153373871 -0.00068616980371472708 0 0 0</pose>
          <mass>0.26543</mass>
          <inertia>
            <ixx>0.00022207061196455799</ixx>
            <ixy>1.3733452147697079e-05</ixy>
            <ixz>1.761767480523045e-05</ixz>
            <iyy>0.00085407162547132065</iyy>
            <iyz>-2.2621806343336801e-06</iyz>
            <izz>0.00072270288582072816</izz>
          </inertia>
        </inertial>
        <collision name='left_wrist_yaw_link_fixed_joint_lump__L_hand_base_link_collision'>
          <pose>0.053999999999999999 0 0 0 0 1.5707963267948959</pose>
          <geometry>
            <mesh>
              <scale>1 1 1</scale>
              <uri>./h1_2_meshes/L_hand_base_link.STL</uri>
            </mesh>
          </geometry>
        </collision>
        <visual name='left_wrist_yaw_link_visual'>
          <pose>0 0 0 0 0 0</pose>
          <geometry>
            <mesh>
              <scale>1 1 1</scale>
              <uri>./h1_2_meshes/wrist_yaw_link.STL</uri>
            </mesh>
          </geometry>
          <material>
            <diffuse>0.125 0.125 0.125 1</diffuse>
            <ambient>0.125 0.125 0.125 1</ambient>
          </material>
        </visual>
        <visual name='left_wrist_yaw_link_fixed_joint_lump__L_hand_base_link_visual_1'>
          <pose>0.053999999999999999 0 0 0 0 1.5707963267948959</pose>
          <geometry>
            <mesh>
              <scale>1 1 1</scale>
              <uri>./h1_2_meshes/L_hand_base_link.STL</uri>
            </mesh>
          </geometry>
          <material>
            <diffuse>0.125 0.125 0.125 1</diffuse>
            <ambient>0.125 0.125 0.125 1</ambient>
          </material>
        </visual>
        <enable_wind>false</enable_wind>
      </link>
      <joint name='L_index_proximal_joint' type='revolute'>
        <pose>-5.5511151231257827e-17 -3.3306690738754696e-16 -1.3877787807814457e-17
          -3.4694469519536142e-18 -3.4694469519536142e-18 6.018531076210112e-36</pose>
        <parent>left_wrist_yaw_link</parent>
        <child>L_index_proximal</child>
        <axis>
          <xyz>3.4694469519536142e-18 -3.4694469519536142e-18 -1</xyz>
          <limit>
            <lower>0</lower>
            <upper>1.7</upper>
            <effort>1</effort>
            <velocity>0.5</velocity>
            <stiffness>100000000</stiffness>
            <dissipation>1</dissipation>
          </limit>
          <dynamics>
            <spring_reference>0</spring_reference>
            <spring_stiffness>0</spring_stiffness>
            <damping>0</damping>
            <friction>0</friction>
          </dynamics>
        </axis>
      </joint>
      <link name='L_index_proximal'>
        <pose>0.42452999999999985 0.20978495800064889 0.12724794211456247 -0.034907000000000021
          -3.8163916471489756e-17 1.5707963267948988</pose>
        <inertial>
          <pose>0.0012971 -0.011934 -0.0059997999999999996 0 0 0</pose>
          <mass>0.0042405000000000003</mass>
          <inertia>
            <ixx>6.6214999999999998e-07</ixx>
            <ixy>1.8442000000000001e-08</ixy>
            <ixz>1.3746e-12</ixz>
            <iyy>2.1166999999999999e-07</iyy>
            <iyz>-1.4773000000000001e-11</iyz>
            <izz>6.9401999999999996e-07</izz>
          </inertia>
        </inertial>
        <collision name='L_index_proximal_collision'>
          <pose>0 0 0 0 0 0</pose>
          <geometry>
            <mesh>
              <scale>1 1 1</scale>
              <uri>./h1_2_meshes/link15_L.STL</uri>
            </mesh>
          </geometry>
        </collision>
        <visual name='L_index_proximal_visual'>
          <pose>0 0 0 0 0 0</pose>
          <geometry>
            <mesh>
              <scale>1 1 1</scale>
              <uri>./h1_2_meshes/link15_L.STL</uri>
            </mesh>
          </geometry>
          <material>
            <diffuse>0.125 0.125 0.125 1</diffuse>
            <ambient>0.125 0.125 0.125 1</ambient>
          </material>
        </visual>
        <enable_wind>false</enable_wind>
      </link>
      <joint name='L_index_intermediate_joint' type='revolute'>
        <pose>-1.3877787807814457e-16 -3.3306690738754696e-16 -1.3877787807814457e-17
          -3.4694469519536142e-18 -3.4694469519536142e-18 6.018531076210112e-36</pose>
        <parent>L_index_proximal</parent>
        <child>L_index_intermediate</child>
        <axis>
          <xyz>3.4694469519536142e-18 -3.4694469519536142e-18 -1</xyz>
          <limit>
            <lower>0</lower>
            <upper>1.7</upper>
            <effort>1</effort>
            <velocity>0.5</velocity>
            <stiffness>100000000</stiffness>
            <dissipation>1</dissipation>
          </limit>
          <dynamics>
            <spring_reference>0</spring_reference>
            <spring_stiffness>0</spring_stiffness>
            <damping>0</damping>
            <friction>0</friction>
          </dynamics>
          <mimic joint='L_index_proximal_joint' axis='axis'>
            <multiplier>1</multiplier>
            <offset>0</offset>
            <reference>0</reference>
          </mimic>
        </axis>
      </joint>
      <link name='L_index_intermediate'>
        <pose>0.45658638093591125 0.20736205800064889 0.1273667793635076 -0.034907000000000021
          -3.8163916471489756e-17 1.5707963267948988</pose>
        <inertial>
          <pose>0.0021752999999999998 -0.019567000000000001 -0.0050000000000000001 0 0 0</pose>
          <mass>0.0045681999999999997</mass>
          <inertia>
            <ixx>7.6283999999999997e-07</ixx>
            <ixy>-8.0630000000000001e-08</ixy>
            <ixz>3.6797e-13</ixz>
            <iyy>9.4308e-08</iyy>
            <iyz>1.5742999999999999e-13</iyz>
            <izz>7.8176000000000003e-07</izz>
          </inertia>
        </inertial>
        <collision name='L_index_intermediate_collision'>
          <pose>0 0 0 0 0 0</pose>
          <geometry>
            <mesh>
              <scale>1 1 1</scale>
              <uri>./h1_2_meshes/link16_L.STL</uri>
            </mesh>
          </geometry>
        </collision>
        <visual name='L_index_intermediate_visual'>
          <pose>0 0 0 0 0 0</pose>
          <geometry>
            <mesh>
              <scale>1 1 1</scale>
              <uri>./h1_2_meshes/link16_L.STL</uri>
            </mesh>
          </geometry>
          <material>
            <diffuse>0.125 0.125 0.125 1</diffuse>
            <ambient>0.125 0.125 0.125 1</ambient>
          </material>
        </visual>
        <enable_wind>false</enable_wind>
      </link>
      <joint name='L_middle_proximal_joint' type='revolute'>
        <pose>-8.3266726846886741e-17 5.5511151231257827e-17 1.3877787807814457e-17 0 0 0</pose>
        <parent>left_wrist_yaw_link</parent>
        <child>L_middle_proximal</child>
        <axis>
          <xyz>0 0 -1</xyz>
          <limit>
            <lower>0</lower>
            <upper>1.7</upper>
            <effort>1</effort>
            <velocity>0.5</velocity>
            <stiffness>100000000</stiffness>
            <dissipation>1</dissipation>
          </limit>
          <dynamics>
            <spring_reference>0</spring_reference>
            <spring_stiffness>0</spring_stiffness>
            <damping>0</damping>
            <friction>0</friction>
          </dynamics>
        </axis>
      </joint>
      <link name='L_middle_proximal'>
        <pose>0.42509999999999987 0.20978495800064889 0.10792994211456253 -1.9626155733547196e-17
          1.962615573354718e-17 1.5707963267948959</pose>
        <inertial>
          <pose>0.0012971 -0.011934 -0.0059998999999999999 0 0 0</pose>
          <mass>0.0042405000000000003</mass>
          <inertia>
            <ixx>6.6214999999999998e-07</ixx>
            <ixy>1.8442000000000001e-08</ixy>
            <ixz>1.2299e-12</ixz>
            <iyy>2.1166999999999999e-07</iyy>
            <iyz>-1.4484e-11</iyz>
            <izz>6.9401999999999996e-07</izz>
          </inertia>
        </inertial>
        <collision name='L_middle_proximal_collision'>
          <pose>0 0 0 0 0 0</pose>
          <geometry>
            <mesh>
              <scale>1 1 1</scale>
              <uri>./h1_2_meshes/link17_L.STL</uri>
            </mesh>
          </geometry>
        </collision>
        <visual name='L_middle_proximal_visual'>
          <pose>0 0 0 0 0 0</pose>
          <geometry>
            <mesh>
              <scale>1 1 1</scale>
              <uri>./h1_2_meshes/link17_L.STL</uri>
            </mesh>
          </geometry>
          <material>
            <diffuse>0.125 0.125 0.125 1</diffuse>
            <ambient>0.125 0.125 0.125 1</ambient>
          </material>
        </visual>
        <enable_wind>false</enable_wind>
      </link>
      <joint name='L_middle_intermediate_joint' type='revolute'>
        <pose>0 0 1.3877787807814457e-17 0 0 0</pose>
        <parent>L_middle_proximal</parent>
        <child>L_middle_intermediate</child>
        <axis>
          <xyz>0 0 -1</xyz>
          <limit>
            <lower>0</lower>
            <upper>1.7</upper>
            <effort>1</effort>
            <velocity>0.5</velocity>
            <stiffness>100000000</stiffness>
            <dissipation>1</dissipation>
          </limit>
          <dynamics>
            <spring_reference>0</spring_reference>
            <spring_stiffness>0</spring_stiffness>
            <damping>0</damping>
            <friction>0</friction>
          </dynamics>
          <mimic joint='L_middle_proximal_joint' axis='axis'>
            <multiplier>1</multiplier>
            <offset>0</offset>
            <reference>0</reference>
          </mimic>
        </axis>
      </joint>
      <link name='L_middle_intermediate'>
        <pose>0.45714099999999996 0.20736205800064883 0.10692994211456264 -1.9626155733547196e-17
          1.962615573354718e-17 1.5707963267948959</pose>
        <inertial>
          <pose>0.001921 -0.020795999999999999 -0.0049998999999999998 0 0 0</pose>
          <mass>0.0050397000000000003</mass>
          <inertia>
            <ixx>9.5822999999999997e-07</ixx>
            <ixy>-1.1424999999999999e-07</ixy>
            <ixz>-2.4185999999999998e-12</ixz>
            <iyy>1.0646e-07</iyy>
            <iyz>3.6974e-12</iyz>
            <izz>9.8384999999999991e-07</izz>
          </inertia>
        </inertial>
        <collision name='L_middle_intermediate_collision'>
          <pose>0 0 0 0 0 0</pose>
          <geometry>
            <mesh>
              <scale>1 1 1</scale>
              <uri>./h1_2_meshes/link18_L.STL</uri>
            </mesh>
          </geometry>
        </collision>
        <visual name='L_middle_intermediate_visual'>
          <pose>0 0 0 0 0 0</pose>
          <geometry>
            <mesh>
              <scale>1 1 1</scale>
              <uri>./h1_2_meshes/link18_L.STL</uri>
            </mesh>
          </geometry>
          <material>
            <diffuse>0.125 0.125 0.125 1</diffuse>
            <ambient>0.125 0.125 0.125 1</ambient>
          </material>
        </visual>
        <enable_wind>false</enable_wind>
      </link>
      <joint name='L_pinky_proximal_joint' type='revolute'>
        <pose>-1.6653345369377348e-16 -2.7755575615628914e-16 1.3877787807814457e-17
          -1.3877787807814457e-17 6.9388939039072284e-18 -4.8148248609680896e-35</pose>
        <parent>left_wrist_yaw_link</parent>
        <child>L_pinky_proximal</child>
        <axis>
          <xyz>-6.9388939039072284e-18 -1.3877787807814457e-17 -1</xyz>
          <limit>
            <lower>0</lower>
            <upper>1.7</upper>
            <effort>1</effort>
            <velocity>0.5</velocity>
            <stiffness>100000000</stiffness>
            <dissipation>1</dissipation>
          </limit>
          <dynamics>
            <spring_reference>0</spring_reference>
            <spring_stiffness>0</spring_stiffness>
            <damping>0</damping>
            <friction>0</friction>
          </dynamics>
        </axis>
      </joint>
      <link name='L_pinky_proximal'>
        <pose>0.42370999999999998 0.20978495800064886 0.069491942114562555 0.10472000000000012
          -5.5511151231257827e-17 1.5707963267948986</pose>
        <inertial>
          <pose>0.0012971 -0.011934 -0.0059998999999999999 0 0 0</pose>
          <mass>0.0042405000000000003</mass>
          <inertia>
            <ixx>6.6214999999999998e-07</ixx>
            <ixy>1.8442000000000001e-08</ixy>
            <ixz>1.0279000000000001e-12</ixz>
            <iyy>2.1166999999999999e-07</iyy>
            <iyz>-1.4277e-11</iyz>
            <izz>6.9401999999999996e-07</izz>
          </inertia>
        </inertial>
        <collision name='L_pinky_proximal_collision'>
          <pose>0 0 0 0 0 0</pose>
          <geometry>
            <mesh>
              <scale>1 1 1</scale>
              <uri>./h1_2_meshes/link21_L.STL</uri>
            </mesh>
          </geometry>
        </collision>
        <visual name='L_pinky_proximal_visual'>
          <pose>0 0 0 0 0 0</pose>
          <geometry>
            <mesh>
              <scale>1 1 1</scale>
              <uri>./h1_2_meshes/link21_L.STL</uri>
            </mesh>
          </geometry>
          <material>
            <diffuse>0.125 0.125 0.125 1</diffuse>
            <ambient>0.125 0.125 0.125 1</ambient>
          </material>
        </visual>
        <enable_wind>false</enable_wind>
      </link>
      <joint name='L_pinky_intermediate_joint' type='revolute'>
        <pose>-2.7755575615628914e-17 -3.3306690738754696e-16 1.3877787807814457e-17
          -1.3877787807814457e-17 6.9388939039072284e-18 -4.8148248609680896e-35</pose>
        <parent>L_pinky_proximal</parent>
        <child>L_pinky_intermediate</child>
        <axis>
          <xyz>-6.9388939039072284e-18 -1.3877787807814457e-17 -1</xyz>
          <limit>
            <lower>0</lower>
            <upper>1.7</upper>
            <effort>1</effort>
            <velocity>0.5</velocity>
            <stiffness>100000000</stiffness>
            <dissipation>1</dissipation>
          </limit>
          <dynamics>
            <spring_reference>0</spring_reference>
            <spring_stiffness>0</spring_stiffness>
            <damping>0</damping>
            <friction>0</friction>
          </dynamics>
          <mimic joint='L_pinky_proximal_joint' axis='axis'>
            <multiplier>1</multiplier>
            <offset>0</offset>
            <reference>0</reference>
          </mimic>
        </axis>
      </joint>
      <link name='L_pinky_intermediate'>
        <pose>0.45547094652253495 0.20736205800064886 0.065148215950003863 0.10472000000000019
          -1.0408340855860843e-16 1.5707963267948997</pose>
        <inertial>
          <pose>0.0024788000000000002 -0.016208 -0.0050001000000000004 0 0 0</pose>
          <mass>0.0036036000000000002</mass>
          <inertia>
            <ixx>4.3923e-07</ixx>
            <ixy>-4.1355000000000002e-08</ixy>
            <ixz>1.2262999999999999e-12</ixz>
            <iyy>7.0315000000000005e-08</iyy>
            <iyz>3.1310999999999999e-12</iyz>
            <izz>4.4881000000000001e-07</izz>
          </inertia>
        </inertial>
        <collision name='L_pinky_intermediate_collision'>
          <pose>0 0 0 0 0 0</pose>
          <geometry>
            <mesh>
              <scale>1 1 1</scale>
              <uri>./h1_2_meshes/link22_L.STL</uri>
            </mesh>
          </geometry>
        </collision>
        <visual name='L_pinky_intermediate_visual'>
          <pose>0 0 0 0 0 0</pose>
          <geometry>
            <mesh>
              <scale>1 1 1</scale>
              <uri>./h1_2_meshes/link22_L.STL</uri>
            </mesh>
          </geometry>
          <material>
            <diffuse>0.125 0.125 0.125 1</diffuse>
            <ambient>0.125 0.125 0.125 1</ambient>
          </material>
        </visual>
        <enable_wind>false</enable_wind>
      </link>
      <joint name='L_ring_proximal_joint' type='revolute'>
        <pose>-1.9428902930940239e-16 0 0 0 3.4694469519536142e-18 0</pose>
        <parent>left_wrist_yaw_link</parent>
        <child>L_ring_proximal</child>
        <axis>
          <xyz>-3.4694469519536142e-18 0 -1</xyz>
          <limit>
            <lower>0</lower>
            <upper>1.7</upper>
            <effort>1</effort>
            <velocity>0.5</velocity>
            <stiffness>100000000</stiffness>
            <dissipation>1</dissipation>
          </limit>
          <dynamics>
            <spring_reference>0</spring_reference>
            <spring_stiffness>0</spring_stiffness>
            <damping>0</damping>
            <friction>0</friction>
          </dynamics>
        </axis>
      </joint>
      <link name='L_ring_proximal'>
        <pose>0.4249099999999999 0.20978495800064889 0.088692742114562684 0.05235999999999999
          1.0408340855860843e-17 1.570796326794897</pose>
        <inertial>
          <pose>0.0012971 -0.011934 -0.0059998999999999999 0 0 0</pose>
          <mass>0.0042405000000000003</mass>
          <inertia>
            <ixx>6.6214999999999998e-07</ixx>
            <ixy>1.8442000000000001e-08</ixy>
            <ixz>9.6052000000000003e-13</ixz>
            <iyy>2.1166999999999999e-07</iyy>
            <iyz>-1.4124000000000001e-11</iyz>
            <izz>6.9401999999999996e-07</izz>
          </inertia>
        </inertial>
        <collision name='L_ring_proximal_collision'>
          <pose>0 0 0 0 0 0</pose>
          <geometry>
            <mesh>
              <scale>1 1 1</scale>
              <uri>./h1_2_meshes/link19_L.STL</uri>
            </mesh>
          </geometry>
        </collision>
        <visual name='L_ring_proximal_visual'>
          <pose>0 0 0 0 0 0</pose>
          <geometry>
            <mesh>
              <scale>1 1 1</scale>
              <uri>./h1_2_meshes/link19_L.STL</uri>
            </mesh>
          </geometry>
          <material>
            <diffuse>0.125 0.125 0.125 1</diffuse>
            <ambient>0.125 0.125 0.125 1</ambient>
          </material>
        </visual>
        <enable_wind>false</enable_wind>
      </link>
      <joint name='L_ring_intermediate_joint' type='revolute'>
        <pose>0 0 -1.3877787807814457e-17 0 3.4694469519536142e-18 0</pose>
        <parent>L_ring_proximal</parent>
        <child>L_ring_intermediate</child>
        <axis>
          <xyz>-3.4694469519536142e-18 0 -1</xyz>
          <limit>
            <lower>0</lower>
            <upper>1.7</upper>
            <effort>1</effort>
            <velocity>0.5</velocity>
            <stiffness>100000000</stiffness>
            <dissipation>1</dissipation>
          </limit>
          <dynamics>
            <spring_reference>0</spring_reference>
            <spring_stiffness>0</spring_stiffness>
            <damping>0</damping>
            <friction>0</friction>
          </dynamics>
          <mimic joint='L_ring_proximal_joint' axis='axis'>
            <multiplier>1</multiplier>
            <offset>0</offset>
            <reference>0</reference>
          </mimic>
        </axis>
      </joint>
      <link name='L_ring_intermediate'>
        <pose>0.45685475263923608 0.20736205800064889 0.086017212294506873 0.05235999999999999
          -3.4694469519536142e-18 1.5707963267948974</pose>
        <inertial>
          <pose>0.0021752999999999998 -0.019567000000000001 -0.0050000000000000001 0 0 0</pose>
          <mass>0.0045681999999999997</mass>
          <inertia>
            <ixx>7.6285000000000003e-07</ixx>
            <ixy>-8.0631000000000002e-08</ixy>
            <ixz>3.3472000000000001e-14</ixz>
            <iyy>9.4308e-08</iyy>
            <iyz>-4.4773e-13</iyz>
            <izz>7.8176000000000003e-07</izz>
          </inertia>
        </inertial>
        <collision name='L_ring_intermediate_collision'>
          <pose>0 0 0 0 0 0</pose>
          <geometry>
            <mesh>
              <scale>1 1 1</scale>
              <uri>./h1_2_meshes/link20_L.STL</uri>
            </mesh>
          </geometry>
        </collision>
        <visual name='L_ring_intermediate_visual'>
          <pose>0 0 0 0 0 0</pose>
          <geometry>
            <mesh>
              <scale>1 1 1</scale>
              <uri>./h1_2_meshes/link20_L.STL</uri>
            </mesh>
          </geometry>
          <material>
            <diffuse>0.125 0.125 0.125 1</diffuse>
            <ambient>0.125 0.125 0.125 1</ambient>
          </material>
        </visual>
        <enable_wind>false</enable_wind>
      </link>
      <joint name='L_thumb_proximal_yaw_joint' type='revolute'>
        <pose>8.3266726846886741e-17 0 0 0 0 0</pose>
        <parent>left_wrist_yaw_link</parent>
        <child>L_thumb_proximal_base</child>
        <axis>
          <xyz>0 0 1</xyz>
          <limit>
            <lower>-0.10000000000000001</lower>
            <upper>1.3</upper>
            <effort>1</effort>
            <velocity>0.5</velocity>
            <stiffness>100000000</stiffness>
            <dissipation>1</dissipation>
          </limit>
          <dynamics>
            <spring_reference>0</spring_reference>
            <spring_stiffness>0</spring_stiffness>
            <damping>0</damping>
            <friction>0</friction>
          </dynamics>
        </axis>
      </joint>
      <link name='L_thumb_proximal_base'>
        <pose>0.35709999999999992 0.19253962800064889 0.11542994211456259 -1.5707926536511043
          -1.5707926535755432 -1.5707963267344476</pose>
        <inertial>
          <pose>0.0048817000000000001 0.00038781999999999998 -0.0072199999999999999 0 0 0</pose>
          <mass>0.0018868999999999999</mass>
          <inertia>
            <ixx>5.5158000000000003e-08</ixx>
            <ixy>-1.1803e-08</ixy>
            <ixz>-4.6742999999999999e-09</ixz>
            <iyy>8.2163999999999994e-08</iyy>
            <iyz>-1.3520999999999999e-09</iyz>
            <izz>6.7433999999999994e-08</izz>
          </inertia>
        </inertial>
        <collision name='L_thumb_proximal_base_collision'>
          <pose>0 0 0 0 0 0</pose>
          <geometry>
            <mesh>
              <scale>1 1 1</scale>
              <uri>./h1_2_meshes/link11_L.STL</uri>
            </mesh>
          </geometry>
        </collision>
        <visual name='L_thumb_proximal_base_visual'>
          <pose>0 0 0 0 0 0</pose>
          <geometry>
            <mesh>
              <scale>1 1 1</scale>
              <uri>./h1_2_meshes/link11_L.STL</uri>
            </mesh>
          </geometry>
          <material>
            <diffuse>0.125 0.125 0.125 1</diffuse>
            <ambient>0.125 0.125 0.125 1</ambient>
          </material>
        </visual>
        <enable_wind>false</enable_wind>
      </link>
      <joint name='L_thumb_proximal_pitch_joint' type='revolute'>
        <pose>-1.2490009027033011e-16 -2.2204460492503131e-16 -1.1102230246251565e-16
          5.5511151231257827e-17 5.5511151231257827e-17 -5.5511151231257827e-17</pose>
        <parent>L_thumb_proximal_base</parent>
        <child>L_thumb_proximal</child>
        <axis>
          <xyz>-5.5511151231257827e-17 5.5511151231257827e-17 -1</xyz>
          <limit>
            <lower>-0.10000000000000001</lower>
            <upper>0.59999999999999998</upper>
            <effort>1</effort>
            <velocity>0.5</velocity>
            <stiffness>100000000</stiffness>
            <dissipation>1</dissipation>
          </limit>
          <dynamics>
            <spring_reference>0</spring_reference>
            <spring_stiffness>0</spring_stiffness>
            <damping>0</damping>
            <friction>0</friction>
          </dynamics>
        </axis>
      </joint>
      <link name='L_thumb_proximal'>
        <pose>0.34820003608650152 0.18271535862578953 0.12541660602793359 3.1415889804647206
          -1.4014026535755413 -1.5707926536544268</pose>
        <inertial>
          <pose>0.021936000000000001 -0.012789999999999999 -0.0080385999999999999 0 0 0</pose>
          <mass>0.0066100999999999998</mass>
          <inertia>
            <ixx>1.5693e-06</ixx>
            <ixy>7.8339000000000003e-07</ixy>
            <ixz>8.5959000000000003e-10</ixz>
            <iyy>1.7356e-06</iyy>
            <iyz>1.0378000000000001e-09</iyz>
            <izz>2.7870000000000002e-06</izz>
          </inertia>
        </inertial>
        <collision name='L_thumb_proximal_collision'>
          <pose>0 0 0 0 0 0</pose>
          <geometry>
            <mesh>
              <scale>1 1 1</scale>
              <uri>./h1_2_meshes/link12_L.STL</uri>
            </mesh>
          </geometry>
        </collision>
        <visual name='L_thumb_proximal_visual'>
          <pose>0 0 0 0 0 0</pose>
          <geometry>
            <mesh>
              <scale>1 1 1</scale>
              <uri>./h1_2_meshes/link12_L.STL</uri>
            </mesh>
          </geometry>
          <material>
            <diffuse>0.125 0.125 0.125 1</diffuse>
            <ambient>0.125 0.125 0.125 1</ambient>
          </material>
        </visual>
        <enable_wind>false</enable_wind>
      </link>
      <joint name='L_thumb_intermediate_joint' type='revolute'>
        <pose>-1.3877787807814457e-16 -2.2204460492503131e-16 -1.6653345369377348e-16
          5.5511151231257827e-17 5.5511151231257827e-17 -5.5511151231257827e-17</pose>
        <parent>L_thumb_proximal</parent>
        <child>L_thumb_intermediate</child>
        <axis>
          <xyz>-5.5511151231257827e-17 5.5511151231257827e-17 -1</xyz>
          <limit>
            <lower>0</lower>
            <upper>0.80000000000000004</upper>
            <effort>1</effort>
            <velocity>0.5</velocity>
            <stiffness>100000000</stiffness>
            <dissipation>1</dissipation>
          </limit>
          <dynamics>
            <spring_reference>0</spring_reference>
            <spring_stiffness>0</spring_stiffness>
            <damping>0</damping>
            <friction>0</friction>
          </dynamics>
          <mimic joint='L_thumb_proximal_pitch_joint' axis='axis'>
            <multiplier>1.6000000000000001</multiplier>
            <offset>0</offset>
            <reference>0</reference>
          </mimic>
        </axis>
      </joint>
      <link name='L_thumb_intermediate'>
        <pose>0.38275306341824505 0.17607438105521028 0.16899068580156551 3.1415889804647215
          -1.4014026535755366 -1.5707926536544232</pose>
        <inertial>
          <pose>0.0095531000000000001 0.0016282 -0.0072002000000000003 0 0 0</pose>
          <mass>0.0037843999999999998</mass>
          <inertia>
            <ixx>3.6981e-07</ixx>
            <ixy>9.8603e-08</ixy>
            <ixz>-2.8173000000000001e-12</ixz>
            <iyy>3.2394999999999999e-07</iyy>
            <iyz>-2.8028000000000001e-12</iyz>
            <izz>4.6531999999999999e-07</izz>
          </inertia>
        </inertial>
        <collision name='L_thumb_intermediate_collision'>
          <pose>0 0 0 0 0 0</pose>
          <geometry>
            <mesh>
              <scale>1 1 1</scale>
              <uri>./h1_2_meshes/link13_L.STL</uri>
            </mesh>
          </geometry>
        </collision>
        <visual name='L_thumb_intermediate_visual'>
          <pose>0 0 0 0 0 0</pose>
          <geometry>
            <mesh>
              <scale>1 1 1</scale>
              <uri>./h1_2_meshes/link13_L.STL</uri>
            </mesh>
          </geometry>
          <material>
            <diffuse>0.125 0.125 0.125 1</diffuse>
            <ambient>0.125 0.125 0.125 1</ambient>
          </material>
        </visual>
        <enable_wind>false</enable_wind>
      </link>
      <joint name='L_thumb_distal_joint' type='revolute'>
        <pose>-1.6653345369377348e-16 -2.7755575615628914e-16 -1.1102230246251565e-16
          5.5511151231257827e-17 5.5511151231257827e-17 -5.5511151231257827e-17</pose>
        <parent>L_thumb_intermediate</parent>
        <child>L_thumb_distal</child>
        <axis>
          <xyz>-5.5511151231257827e-17 5.5511151231257827e-17 -1</xyz>
          <limit>
            <lower>0</lower>
            <upper>1.2</upper>
            <effort>1</effort>
            <velocity>0.5</velocity>
            <stiffness>100000000</stiffness>
            <dissipation>1</dissipation>
          </limit>
          <dynamics>
            <spring_reference>0</spring_reference>
            <spring_stiffness>0</spring_stiffness>
            <damping>0</damping>
            <friction>0</friction>
          </dynamics>
          <mimic joint='L_thumb_proximal_pitch_joint' axis='axis'>
            <multiplier>2.3999999999999999</multiplier>
            <offset>0</offset>
            <reference>0</reference>
          </mimic>
        </axis>
      </joint>
      <link name='L_thumb_distal'>
        <pose>0.39290907601959074 0.17384370254319426 0.18915117491808586 3.1415889804647201
          -1.4014026535755313 -1.5707926536544166</pose>
        <inertial>
          <pose>0.0092887999999999998 -0.0049529999999999999 -0.0060032999999999996 0 0 0</pose>
          <mass>0.0033440000000000002</mass>
          <inertia>
            <ixx>1.3631999999999999e-07</ixx>
            <ixy>5.6786999999999998e-08</ixy>
            <ixz>-9.1938999999999999e-11</ixz>
            <iyy>1.4051999999999999e-07</iyy>
            <iyz>1.2145e-10</iyz>
            <izz>2.0025999999999999e-07</izz>
          </inertia>
        </inertial>
        <collision name='L_thumb_distal_collision'>
          <pose>0 0 0 0 0 0</pose>
          <geometry>
            <mesh>
              <scale>1 1 1</scale>
              <uri>./h1_2_meshes/link14_L.STL</uri>
            </mesh>
          </geometry>
        </collision>
        <visual name='L_thumb_distal_visual'>
          <pose>0 0 0 0 0 0</pose>
          <geometry>
            <mesh>
              <scale>1 1 1</scale>
              <uri>./h1_2_meshes/link14_L.STL</uri>
            </mesh>
          </geometry>
          <material>
            <diffuse>0.125 0.125 0.125 1</diffuse>
            <ambient>0.125 0.125 0.125 1</ambient>
          </material>
        </visual>
        <enable_wind>false</enable_wind>
      </link>
      <joint name='right_shoulder_pitch_joint' type='revolute'>
        <pose>0 0 -5.5511151231257827e-17 0 0 0</pose>
        <parent>torso_link</parent>
        <child>right_shoulder_pitch_link</child>
        <axis>
          <xyz>0 1 0</xyz>
          <limit>
            <lower>-3.1400000000000001</lower>
            <upper>1.5700000000000001</upper>
            <effort>40</effort>
            <velocity>9</velocity>
            <stiffness>100000000</stiffness>
            <dissipation>1</dissipation>
          </limit>
          <dynamics>
            <spring_reference>0</spring_reference>
            <spring_stiffness>0</spring_stiffness>
            <damping>0</damping>
            <friction>0</friction>
          </dynamics>
        </axis>
      </joint>
      <link name='right_shoulder_pitch_link'>
        <pose>0 -0.14806 0.42332999999999998 -0.2618000000000002 0 0</pose>
        <inertial>
          <pose>0.0030530000000000002 -0.060420000000000001 -0.0058999999999999999 0 0 0</pose>
          <mass>1.327</mass>
          <inertia>
            <ixx>0.00058661</ixx>
            <ixy>2.0157e-05</ixy>
            <ixz>2.9849999999999998e-06</ixz>
            <iyy>0.00039889999999999999</iyy>
            <iyz>-2.2379999999999999e-05</iyz>
            <izz>0.00052935999999999999</izz>
          </inertia>
        </inertial>
        <collision name='right_shoulder_pitch_link_collision'>
          <pose>0 0 0 0 0 0</pose>
          <geometry>
            <mesh>
              <scale>1 1 1</scale>
              <uri>
                ./h1_2_meshes/right_shoulder_pitch_link.STL</uri>
            </mesh>
          </geometry>
        </collision>
        <visual name='right_shoulder_pitch_link_visual'>
          <pose>0 0 0 0 0 0</pose>
          <geometry>
            <mesh>
              <scale>1 1 1</scale>
              <uri>
                ./h1_2_meshes/right_shoulder_pitch_link.STL</uri>
            </mesh>
          </geometry>
          <material>
            <diffuse>0.125 0.125 0.125 1</diffuse>
            <ambient>0.125 0.125 0.125 1</ambient>
          </material>
        </visual>
        <enable_wind>false</enable_wind>
      </link>
      <joint name='right_shoulder_roll_joint' type='revolute'>
        <pose>0 0 0 0 0 0</pose>
        <parent>right_shoulder_pitch_link</parent>
        <child>right_shoulder_roll_link</child>
        <axis>
          <xyz>1 0 0</xyz>
          <limit>
            <lower>-3.3999999999999999</lower>
            <upper>0.38</upper>
            <effort>40</effort>
            <velocity>9</velocity>
            <stiffness>100000000</stiffness>
            <dissipation>1</dissipation>
          </limit>
          <dynamics>
            <spring_reference>0</spring_reference>
            <spring_stiffness>0</spring_stiffness>
            <damping>0</damping>
            <friction>0</friction>
          </dynamics>
        </axis>
      </joint>
      <link name='right_shoulder_roll_link'>
        <pose>0.034200000000000001 -0.20949962800064897 0.4335799421145623 0 0 0</pose>
        <inertial>
          <pose>-0.030932000000000001 9.9999999999999995e-07 -0.10609 0 0 0</pose>
          <mass>1.393</mass>
          <inertia>
            <ixx>0.0018408000000000001</ixx>
            <ixy>-3.9799999999999999e-07</ixy>
            <ixz>-0.00048324000000000002</ixz>
            <iyy>0.001934638</iyy>
            <iyz>-1.61e-07</iyz>
            <izz>0.00061773299999999998</izz>
          </inertia>
        </inertial>
        <collision name='right_shoulder_roll_link_collision'>
          <pose>0 0 0 0 0 0</pose>
          <geometry>
            <mesh>
              <scale>1 1 1</scale>
              <uri>
                ./h1_2_meshes/right_shoulder_roll_link.STL</uri>
            </mesh>
          </geometry>
        </collision>
        <visual name='right_shoulder_roll_link_visual'>
          <pose>0 0 0 0 0 0</pose>
          <geometry>
            <mesh>
              <scale>1 1 1</scale>
              <uri>
                ./h1_2_meshes/right_shoulder_roll_link.STL</uri>
            </mesh>
          </geometry>
          <material>
            <diffuse>0.125 0.125 0.125 1</diffuse>
            <ambient>0.125 0.125 0.125 1</ambient>
          </material>
        </visual>
        <enable_wind>false</enable_wind>
      </link>
      <joint name='right_shoulder_yaw_joint' type='revolute'>
        <pose>0 0 0 0 0 0</pose>
        <parent>right_shoulder_roll_link</parent>
        <child>right_shoulder_yaw_link</child>
        <axis>
          <xyz>0 0 1</xyz>
          <limit>
            <lower>-3.0099999999999998</lower>
            <upper>2.6600000000000001</upper>
            <effort>18</effort>
            <velocity>20</velocity>
            <stiffness>100000000</stiffness>
            <dissipation>1</dissipation>
          </limit>
          <dynamics>
            <spring_reference>0</spring_reference>
            <spring_stiffness>0</spring_stiffness>
            <damping>0</damping>
            <friction>0</friction>
          </dynamics>
        </axis>
      </joint>
      <link name='right_shoulder_yaw_link'>
        <pose>0 -0.20949962800064892 0.28797994211456235 0 0 0</pose>
        <inertial>
          <pose>0.0045830000000000003 -0.0011280000000000001 -0.0011280000000000001 0 0 0</pose>
          <mass>1.5049999999999999</mass>
          <inertia>
            <ixx>0.0041989999999999996</ixx>
            <ixy>1.7785999999999999e-05</ixy>
            <ixz>0.00018372000000000001</ixz>
            <iyy>0.0043138999999999999</iyy>
            <iyz>-9.2780000000000003e-05</iyz>
            <izz>0.00065755000000000002</izz>
          </inertia>
        </inertial>
        <collision name='right_shoulder_yaw_link_collision'>
          <pose>0 0 0 0 0 0</pose>
          <geometry>
            <mesh>
              <scale>1 1 1</scale>
              <uri>
                ./h1_2_meshes/right_shoulder_yaw_link.STL</uri>
            </mesh>
          </geometry>
        </collision>
        <visual name='right_shoulder_yaw_link_visual'>
          <pose>0 0 0 0 0 0</pose>
          <geometry>
            <mesh>
              <scale>1 1 1</scale>
              <uri>
                ./h1_2_meshes/right_shoulder_yaw_link.STL</uri>
            </mesh>
          </geometry>
          <material>
            <diffuse>0.125 0.125 0.125 1</diffuse>
            <ambient>0.125 0.125 0.125 1</ambient>
          </material>
        </visual>
        <enable_wind>false</enable_wind>
      </link>
      <joint name='right_elbow_joint' type='revolute'>
        <pose>0 0 0 0 0 0</pose>
        <parent>right_shoulder_yaw_link</parent>
        <child>right_elbow_link</child>
        <axis>
          <xyz>0 1 0</xyz>
          <limit>
            <lower>-0.94999999999999996</lower>
            <upper>3.1800000000000002</upper>
            <effort>18</effort>
            <velocity>20</velocity>
            <stiffness>100000000</stiffness>
            <dissipation>1</dissipation>
          </limit>
          <dynamics>
            <spring_reference>0</spring_reference>
            <spring_stiffness>0</spring_stiffness>
            <damping>0</damping>
            <friction>0</friction>
          </dynamics>
        </axis>
      </joint>
      <link name='right_elbow_link'>
        <pose>0.0059999999999999967 -0.2423996280006489 0.10597994211456241 0 0 0</pose>
        <inertial>
          <pose>0.077091999999999994 0.028750999999999999 -0.0097140000000000004 0 0 0</pose>
          <mass>0.69099999999999995</mass>
          <inertia>
            <ixx>0.00031849100000000001</ixx>
            <ixy>-0.00022455399999999999</ixy>
            <ixz>6.6207599999999999e-05</ixz>
            <iyy>0.00086122399999999995</iyy>
            <iyz>2.3329e-05</iyz>
            <izz>0.00089789899999999996</izz>
          </inertia>
        </inertial>
        <collision name='right_elbow_link_collision'>
          <pose>0 0 0 0 0 0</pose>
          <geometry>
            <mesh>
              <scale>1 1 1</scale>
              <uri>./h1_2_meshes/right_elbow_link.STL</uri>
            </mesh>
          </geometry>
        </collision>
        <visual name='right_elbow_link_visual'>
          <pose>0 0 0 0 0 0</pose>
          <geometry>
            <mesh>
              <scale>1 1 1</scale>
              <uri>./h1_2_meshes/right_elbow_link.STL</uri>
            </mesh>
          </geometry>
          <material>
            <diffuse>0.125 0.125 0.125 1</diffuse>
            <ambient>0.125 0.125 0.125 1</ambient>
          </material>
        </visual>
        <enable_wind>false</enable_wind>
      </link>
      <joint name='right_wrist_roll_joint' type='revolute'>
        <pose>0 0 0 0 0 0</pose>
        <parent>right_elbow_link</parent>
        <child>right_wrist_roll_link</child>
        <axis>
          <xyz>1 0 0</xyz>
          <limit>
            <lower>-2.75</lower>
            <upper>3.0099999999999998</upper>
            <effort>19</effort>
            <velocity>31.399999999999999</velocity>
            <stiffness>100000000</stiffness>
            <dissipation>1</dissipation>
          </limit>
          <dynamics>
            <spring_reference>0</spring_reference>
            <spring_stiffness>0</spring_stiffness>
            <damping>0</damping>
            <friction>0</friction>
          </dynamics>
        </axis>
      </joint>
      <link name='right_wrist_roll_link'>
        <pose>0.127 -0.20949962800064889 0.09497994211456251 0 0 0</pose>
        <inertial>
          <pose>0.035281 -0.00232 0.00033700000000000001 0 0 0</pose>
          <mass>0.68300000000000005</mass>
          <inertia>
            <ixx>0.00031327500000000001</ixx>
            <ixy>1.6521e-05</ixy>
            <ixz>-2.5009999999999999e-06</ixz>
            <iyy>0.00031041199999999998</iyy>
            <iyz>5.4349999999999996e-06</iyz>
            <izz>0.00034599799999999998</izz>
          </inertia>
        </inertial>
        <collision name='right_wrist_roll_link_collision'>
          <pose>0 0 0 0 0 0</pose>
          <geometry>
            <mesh>
              <scale>1 1 1</scale>
              <uri>
                ./h1_2_meshes/right_wrist_roll_link.STL</uri>
            </mesh>
          </geometry>
        </collision>
        <visual name='right_wrist_roll_link_visual'>
          <pose>0 0 0 0 0 0</pose>
          <geometry>
            <mesh>
              <scale>1 1 1</scale>
              <uri>
                ./h1_2_meshes/right_wrist_roll_link.STL</uri>
            </mesh>
          </geometry>
          <material>
            <diffuse>0.125 0.125 0.125 1</diffuse>
            <ambient>0.125 0.125 0.125 1</ambient>
          </material>
        </visual>
        <enable_wind>false</enable_wind>
      </link>
      <joint name='right_wrist_pitch_joint' type='revolute'>
        <pose>0 0 0 0 0 0</pose>
        <parent>right_wrist_roll_link</parent>
        <child>right_wrist_pitch_link</child>
        <axis>
          <xyz>0 1 0</xyz>
          <limit>
            <lower>-0.46250000000000002</lower>
            <upper>0.46250000000000002</upper>
            <effort>19</effort>
            <velocity>31.399999999999999</velocity>
            <stiffness>100000000</stiffness>
            <dissipation>1</dissipation>
          </limit>
          <dynamics>
            <spring_reference>0</spring_reference>
            <spring_stiffness>0</spring_stiffness>
            <damping>0</damping>
            <friction>0</friction>
          </dynamics>
        </axis>
      </joint>
      <link name='right_wrist_pitch_link'>
        <pose>0.214 -0.20949962800064889 0.09497994211456251 0 0 0</pose>
        <inertial>
          <pose>0.020395 3.6000000000000001e-05 -0.0029729999999999999 0 0 0</pose>
          <mass>0.48399999999999999</mass>
          <inertia>
            <ixx>7.1364000000000003e-05</ixx>
            <ixy>3.0800000000000001e-07</ixy>
            <ixz>1.485e-06</ixz>
            <iyy>6.9914999999999997e-05</iyy>
            <iyz>-8.7999999999999994e-08</iyz>
            <izz>7.0702000000000002e-05</izz>
          </inertia>
        </inertial>
        <collision name='right_wrist_pitch_link_collision'>
          <pose>0 0 0 0 0 0</pose>
          <geometry>
            <mesh>
              <scale>1 1 1</scale>
              <uri>
                ./h1_2_meshes/right_wrist_pitch_link.STL</uri>
            </mesh>
          </geometry>
        </collision>
        <visual name='right_wrist_pitch_link_visual'>
          <pose>0 0 0 0 0 0</pose>
          <geometry>
            <mesh>
              <scale>1 1 1</scale>
              <uri>
                ./h1_2_meshes/right_wrist_pitch_link.STL</uri>
            </mesh>
          </geometry>
          <material>
            <diffuse>0.125 0.125 0.125 1</diffuse>
            <ambient>0.125 0.125 0.125 1</ambient>
          </material>
        </visual>
        <enable_wind>false</enable_wind>
      </link>
      <joint name='right_wrist_yaw_joint' type='revolute'>
        <pose>0 0 0 0 0 0</pose>
        <parent>right_wrist_pitch_link</parent>
        <child>right_wrist_yaw_link</child>
        <axis>
          <xyz>0 0 1</xyz>
          <limit>
            <lower>-1.27</lower>
            <upper>1.27</upper>
            <effort>19</effort>
            <velocity>31.399999999999999</velocity>
            <stiffness>100000000</stiffness>
            <dissipation>1</dissipation>
          </limit>
          <dynamics>
            <spring_reference>0</spring_reference>
            <spring_stiffness>0</spring_stiffness>
            <damping>0</damping>
            <friction>0</friction>
          </dynamics>
        </axis>
      </joint>
      <link name='right_wrist_yaw_link'>
        <pose>0.23399999999999996 -0.20949962800064889 0.09497994211456251 0 0 0</pose>
        <inertial>
          <pose>0.077030310100591484 0.001301302610857863 -0.00069901109143654121 0 0 0</pose>
          <mass>0.26543</mass>
          <inertia>
            <ixx>0.00022206760364683499</ixx>
            <ixy>-1.3612189426566221e-05</ixy>
            <ixz>1.7705995601135101e-05</ixz>
            <iyy>0.00085349018180110774</iyy>
            <iyz>2.263508995486718e-06</iyz>
            <izz>0.00072212632117321803</izz>
          </inertia>
        </inertial>
        <collision name='right_wrist_yaw_link_fixed_joint_lump__R_hand_base_link_collision'>
          <pose>0.053999999999999999 0 0 3.1415926535897931 0 -1.5707963267948959</pose>
          <geometry>
            <mesh>
              <scale>1 1 1</scale>
              <uri>./h1_2_meshes/R_hand_base_link.STL</uri>
            </mesh>
          </geometry>
        </collision>
        <visual name='right_wrist_yaw_link_visual'>
          <pose>0 0 0 0 0 0</pose>
          <geometry>
            <mesh>
              <scale>1 1 1</scale>
              <uri>./h1_2_meshes/wrist_yaw_link.STL</uri>
            </mesh>
          </geometry>
          <material>
            <diffuse>0.125 0.125 0.125 1</diffuse>
            <ambient>0.125 0.125 0.125 1</ambient>
          </material>
        </visual>
        <visual name='right_wrist_yaw_link_fixed_joint_lump__R_hand_base_link_visual_1'>
          <pose>0.053999999999999999 0 0 3.1415926535897931 0 -1.5707963267948959</pose>
          <geometry>
            <mesh>
              <scale>1 1 1</scale>
              <uri>./h1_2_meshes/R_hand_base_link.STL</uri>
            </mesh>
          </geometry>
          <material>
            <diffuse>0.125 0.125 0.125 1</diffuse>
            <ambient>0.125 0.125 0.125 1</ambient>
          </material>
        </visual>
        <enable_wind>false</enable_wind>
      </link>
      <joint name='R_index_proximal_joint' type='revolute'>
        <pose>0 3.8857805861880479e-16 1.3877787807814457e-17 -3.4694469519536142e-18 0 0</pose>
        <parent>right_wrist_yaw_link</parent>
        <child>R_index_proximal</child>
        <axis>
          <xyz>0 3.4694469519536142e-18 1</xyz>
          <limit>
            <lower>0</lower>
            <upper>1.7</upper>
            <effort>1</effort>
            <velocity>0.5</velocity>
            <stiffness>100000000</stiffness>
            <dissipation>1</dissipation>
          </limit>
          <dynamics>
            <spring_reference>0</spring_reference>
            <spring_stiffness>0</spring_stiffness>
            <damping>0</damping>
            <friction>0</friction>
          </dynamics>
        </axis>
      </joint>
      <link name='R_index_proximal'>
        <pose>0.42452999999999985 -0.20978495800064889 0.12724794211456247 0.034892653589793099
          -3.4694469519536142e-18 -1.5707963267948974</pose>
        <inertial>
          <pose>0.0012259 0.011941999999999999 -0.0060001000000000004 0 0 0</pose>
          <mass>0.0042402999999999998</mass>
          <inertia>
            <ixx>6.6232000000000002e-07</ixx>
            <ixy>-1.5775000000000001e-08</ixy>
            <ixz>1.8514999999999999e-12</ixz>
            <iyy>2.1145999999999999e-07</iyy>
            <iyz>-5.0828000000000001e-12</iyz>
            <izz>6.9398000000000002e-07</izz>
          </inertia>
        </inertial>
        <collision name='R_index_proximal_collision'>
          <pose>0 0 0 0 0 0</pose>
          <geometry>
            <mesh>
              <scale>1 1 1</scale>
              <uri>./h1_2_meshes/link15_R.STL</uri>
            </mesh>
          </geometry>
        </collision>
        <visual name='R_index_proximal_visual'>
          <pose>0 0 0 0 0 0</pose>
          <geometry>
            <mesh>
              <scale>1 1 1</scale>
              <uri>./h1_2_meshes/link15_R.STL</uri>
            </mesh>
          </geometry>
          <material>
            <diffuse>0.125 0.125 0.125 1</diffuse>
            <ambient>0.125 0.125 0.125 1</ambient>
          </material>
        </visual>
        <enable_wind>false</enable_wind>
      </link>
      <joint name='R_index_intermediate_joint' type='revolute'>
        <pose>-5.5511151231257827e-17 3.8857805861880479e-16 -1.3877787807814457e-17
          -3.4694469519536142e-18 0 0</pose>
        <parent>R_index_proximal</parent>
        <child>R_index_intermediate</child>
        <axis>
          <xyz>0 3.4694469519536142e-18 1</xyz>
          <limit>
            <lower>0</lower>
            <upper>1.7</upper>
            <effort>1</effort>
            <velocity>0.5</velocity>
            <stiffness>100000000</stiffness>
            <dissipation>1</dissipation>
          </limit>
          <dynamics>
            <spring_reference>0</spring_reference>
            <spring_stiffness>0</spring_stiffness>
            <damping>0</damping>
            <friction>0</friction>
          </dynamics>
          <mimic joint='R_index_proximal_joint' axis='axis'>
            <multiplier>1</multiplier>
            <offset>0</offset>
            <reference>0</reference>
          </mimic>
        </axis>
      </joint>
      <link name='R_index_intermediate'>
        <pose>0.45657139176780337 -0.20717115800064892 0.12736579618589872 0.034892653589793099
          -3.4694469519536142e-18 -1.5707963267948968</pose>
        <inertial>
          <pose>0.0019697 0.019588999999999999 -0.0050000000000000001 0 0 0</pose>
          <mass>0.0045683</mass>
          <inertia>
            <ixx>7.6110999999999996e-07</ixx>
            <ixy>8.7637000000000006e-08</ixy>
            <ixz>-3.7751000000000002e-13</ixz>
            <iyy>9.6076000000000006e-08</iyy>
            <iyz>9.9443999999999995e-13</iyz>
            <izz>7.8179000000000001e-07</izz>
          </inertia>
        </inertial>
        <collision name='R_index_intermediate_collision'>
          <pose>0 0 0 0 0 0</pose>
          <geometry>
            <mesh>
              <scale>1 1 1</scale>
              <uri>./h1_2_meshes/link16_R.STL</uri>
            </mesh>
          </geometry>
        </collision>
        <visual name='R_index_intermediate_visual'>
          <pose>0 0 0 0 0 0</pose>
          <geometry>
            <mesh>
              <scale>1 1 1</scale>
              <uri>./h1_2_meshes/link16_R.STL</uri>
            </mesh>
          </geometry>
          <material>
            <diffuse>0.125 0.125 0.125 1</diffuse>
            <ambient>0.125 0.125 0.125 1</ambient>
          </material>
        </visual>
        <enable_wind>false</enable_wind>
      </link>
      <joint name='R_middle_proximal_joint' type='revolute'>
        <pose>-2.2204460492503131e-16 3.8857805861880479e-16 0 0 0 0</pose>
        <parent>right_wrist_yaw_link</parent>
        <child>R_middle_proximal</child>
        <axis>
          <xyz>0 0 1</xyz>
          <limit>
            <lower>0</lower>
            <upper>1.7</upper>
            <effort>1</effort>
            <velocity>0.5</velocity>
            <stiffness>100000000</stiffness>
            <dissipation>1</dissipation>
          </limit>
          <dynamics>
            <spring_reference>0</spring_reference>
            <spring_stiffness>0</spring_stiffness>
            <damping>0</damping>
            <friction>0</friction>
          </dynamics>
        </axis>
      </joint>
      <link name='R_middle_proximal'>
        <pose>0.42509999999999987 -0.20978495800064889 0.10792994211456253 -7.3464102068078937e-06
          1.9626176904355766e-17 -1.5707963267948963</pose>
        <inertial>
          <pose>0.001297 0.011934 -0.0060001000000000004 0 0 0</pose>
          <mass>0.0042402999999999998</mass>
          <inertia>
            <ixx>6.6211000000000004e-07</ixx>
            <ixy>-1.8460999999999999e-08</ixy>
            <ixz>1.8001999999999999e-12</ixz>
            <iyy>2.1166999999999999e-07</iyy>
            <iyz>-6.6808000000000004e-12</iyz>
            <izz>6.9396999999999996e-07</izz>
          </inertia>
        </inertial>
        <collision name='R_middle_proximal_collision'>
          <pose>0 0 0 0 0 0</pose>
          <geometry>
            <mesh>
              <scale>1 1 1</scale>
              <uri>./h1_2_meshes/link17_R.STL</uri>
            </mesh>
          </geometry>
        </collision>
        <visual name='R_middle_proximal_visual'>
          <pose>0 0 0 0 0 0</pose>
          <geometry>
            <mesh>
              <scale>1 1 1</scale>
              <uri>./h1_2_meshes/link17_R.STL</uri>
            </mesh>
          </geometry>
          <material>
            <diffuse>0.125 0.125 0.125 1</diffuse>
            <ambient>0.125 0.125 0.125 1</ambient>
          </material>
        </visual>
        <enable_wind>false</enable_wind>
      </link>
      <joint name='R_middle_intermediate_joint' type='revolute'>
        <pose>-1.3877787807814457e-16 4.4408920985006262e-16 0 0 0 0</pose>
        <parent>R_middle_proximal</parent>
        <child>R_middle_intermediate</child>
        <axis>
          <xyz>0 0 1</xyz>
          <limit>
            <lower>0</lower>
            <upper>1.7</upper>
            <effort>1</effort>
            <velocity>0.5</velocity>
            <stiffness>100000000</stiffness>
            <dissipation>1</dissipation>
          </limit>
          <dynamics>
            <spring_reference>0</spring_reference>
            <spring_stiffness>0</spring_stiffness>
            <damping>0</damping>
            <friction>0</friction>
          </dynamics>
          <mimic joint='R_middle_proximal_joint' axis='axis'>
            <multiplier>1</multiplier>
            <offset>0</offset>
            <reference>0</reference>
          </mimic>
        </axis>
      </joint>
      <link name='R_middle_intermediate'>
        <pose>0.45714099265272501 -0.20736205800064883 0.10692970672826019 -7.3464102068078937e-06
          1.9626176904355766e-17 -1.5707963267948963</pose>
        <inertial>
          <pose>0.001921 0.020795999999999999 -0.0050000000000000001 0 0 0</pose>
          <mass>0.0050396</mass>
          <inertia>
            <ixx>9.5821999999999991e-07</ixx>
            <ixy>1.1424999999999999e-07</ixy>
            <ixz>-2.4790999999999998e-12</ixz>
            <iyy>1.0646e-07</iyy>
            <iyz>5.9173000000000002e-12</iyz>
            <izz>9.8384000000000005e-07</izz>
          </inertia>
        </inertial>
        <collision name='R_middle_intermediate_collision'>
          <pose>0 0 0 0 0 0</pose>
          <geometry>
            <mesh>
              <scale>1 1 1</scale>
              <uri>./h1_2_meshes/link18_R.STL</uri>
            </mesh>
          </geometry>
        </collision>
        <visual name='R_middle_intermediate_visual'>
          <pose>0 0 0 0 0 0</pose>
          <geometry>
            <mesh>
              <scale>1 1 1</scale>
              <uri>./h1_2_meshes/link18_R.STL</uri>
            </mesh>
          </geometry>
          <material>
            <diffuse>0.125 0.125 0.125 1</diffuse>
            <ambient>0.125 0.125 0.125 1</ambient>
          </material>
        </visual>
        <enable_wind>false</enable_wind>
      </link>
      <joint name='R_pinky_proximal_joint' type='revolute'>
        <pose>-5.5511151231257827e-17 3.8857805861880479e-16 2.7755575615628914e-17
          1.387778780781446e-17 -6.9388939039072299e-18 -4.8148248609680918e-35</pose>
        <parent>right_wrist_yaw_link</parent>
        <child>R_pinky_proximal</child>
        <axis>
          <xyz>-6.9388939039072276e-18 -1.3877787807814455e-17 1</xyz>
          <limit>
            <lower>0</lower>
            <upper>1.7</upper>
            <effort>1</effort>
            <velocity>0.5</velocity>
            <stiffness>100000000</stiffness>
            <dissipation>1</dissipation>
          </limit>
          <dynamics>
            <spring_reference>0</spring_reference>
            <spring_stiffness>0</spring_stiffness>
            <damping>0</damping>
            <friction>0</friction>
          </dynamics>
        </axis>
      </joint>
      <link name='R_pinky_proximal'>
        <pose>0.42370999999999998 -0.20978495800064886 0.069491942114562555 -0.10469265358979327
          -8.3266726846886741e-17 -1.5707963267948979</pose>
        <inertial>
          <pose>0.001297 0.011934 -0.0060001000000000004 0 0 0</pose>
          <mass>0.0042402999999999998</mass>
          <inertia>
            <ixx>6.6211000000000004e-07</ixx>
            <ixy>-1.8460999999999999e-08</ixy>
            <ixz>1.6907000000000001e-12</ixz>
            <iyy>2.1166999999999999e-07</iyy>
            <iyz>-6.9334000000000003e-12</iyz>
            <izz>6.9396999999999996e-07</izz>
          </inertia>
        </inertial>
        <collision name='R_pinky_proximal_collision'>
          <pose>0 0 0 0 0 0</pose>
          <geometry>
            <mesh>
              <scale>1 1 1</scale>
              <uri>./h1_2_meshes/link21_R.STL</uri>
            </mesh>
          </geometry>
        </collision>
        <visual name='R_pinky_proximal_visual'>
          <pose>0 0 0 0 0 0</pose>
          <geometry>
            <mesh>
              <scale>1 1 1</scale>
              <uri>./h1_2_meshes/link21_R.STL</uri>
            </mesh>
          </geometry>
          <material>
            <diffuse>0.125 0.125 0.125 1</diffuse>
            <ambient>0.125 0.125 0.125 1</ambient>
          </material>
        </visual>
        <enable_wind>false</enable_wind>
      </link>
      <joint name='R_pinky_intermediate_joint' type='revolute'>
        <pose>-1.9428902930940239e-16 3.8857805861880479e-16 1.3877787807814457e-17
          1.387778780781446e-17 -6.9388939039072299e-18 -4.8148248609680918e-35</pose>
        <parent>R_pinky_proximal</parent>
        <child>R_pinky_intermediate</child>
        <axis>
          <xyz>-6.9388939039072276e-18 -1.3877787807814455e-17 1</xyz>
          <limit>
            <lower>0</lower>
            <upper>1.7</upper>
            <effort>1</effort>
            <velocity>0.5</velocity>
            <stiffness>100000000</stiffness>
            <dissipation>1</dissipation>
          </limit>
          <dynamics>
            <spring_reference>0</spring_reference>
            <spring_stiffness>0</spring_stiffness>
            <damping>0</damping>
            <friction>0</friction>
          </dynamics>
          <mimic joint='R_pinky_proximal_joint' axis='axis'>
            <multiplier>1</multiplier>
            <offset>0</offset>
            <reference>0</reference>
          </mimic>
        </axis>
      </joint>
      <link name='R_pinky_intermediate'>
        <pose>0.45547106529597675 -0.20736205800064889 0.065149084499499965 -0.10469265358979328
          -8.3266726846886741e-17 -1.5707963267948981</pose>
        <inertial>
          <pose>0.0024748000000000001 0.016202999999999999 -0.0050030999999999999 0 0 0</pose>
          <mass>0.0035996000000000001</mass>
          <inertia>
            <ixx>4.3912999999999999e-07</ixx>
            <ixy>4.1418000000000001e-08</ixy>
            <ixz>3.7168000000000002e-11</ixz>
            <iyy>7.0246999999999994e-08</iyy>
            <iyz>5.8613000000000005e-11</iyz>
            <izz>4.4867000000000001e-07</izz>
          </inertia>
        </inertial>
        <collision name='R_pinky_intermediate_collision'>
          <pose>0 0 0 0 0 0</pose>
          <geometry>
            <mesh>
              <scale>1 1 1</scale>
              <uri>./h1_2_meshes/link22_R.STL</uri>
            </mesh>
          </geometry>
        </collision>
        <visual name='R_pinky_intermediate_visual'>
          <pose>0 0 0 0 0 0</pose>
          <geometry>
            <mesh>
              <scale>1 1 1</scale>
              <uri>./h1_2_meshes/link22_R.STL</uri>
            </mesh>
          </geometry>
          <material>
            <diffuse>0.125 0.125 0.125 1</diffuse>
            <ambient>0.125 0.125 0.125 1</ambient>
          </material>
        </visual>
        <enable_wind>false</enable_wind>
      </link>
      <joint name='R_ring_proximal_joint' type='revolute'>
        <pose>-1.6653345369377348e-16 2.7755575615628914e-16 0 3.4694469519536142e-18
          3.4694469519536142e-18 6.018531076210112e-36</pose>
        <parent>right_wrist_yaw_link</parent>
        <child>R_ring_proximal</child>
        <axis>
          <xyz>3.4694469519536142e-18 -3.4694469519536142e-18 1</xyz>
          <limit>
            <lower>0</lower>
            <upper>1.7</upper>
            <effort>1</effort>
            <velocity>0.5</velocity>
            <stiffness>100000000</stiffness>
            <dissipation>1</dissipation>
          </limit>
          <dynamics>
            <spring_reference>0</spring_reference>
            <spring_stiffness>0</spring_stiffness>
            <damping>0</damping>
            <friction>0</friction>
          </dynamics>
        </axis>
      </joint>
      <link name='R_ring_proximal'>
        <pose>0.4249099999999999 -0.20978495800064889 0.088692742114562684 -0.052392653589793489
          -5.5511151231257827e-17 -1.5707963267948981</pose>
        <inertial>
          <pose>0.001297 0.011934 -0.0060001999999999998 0 0 0</pose>
          <mass>0.0042402999999999998</mass>
          <inertia>
            <ixx>6.6211000000000004e-07</ixx>
            <ixy>-1.8460999999999999e-08</ixy>
            <ixz>1.5792999999999999e-12</ixz>
            <iyy>2.1166999999999999e-07</iyy>
            <iyz>-6.6868000000000001e-12</iyz>
            <izz>6.9396999999999996e-07</izz>
          </inertia>
        </inertial>
        <collision name='R_ring_proximal_collision'>
          <pose>0 0 0 0 0 0</pose>
          <geometry>
            <mesh>
              <scale>1 1 1</scale>
              <uri>./h1_2_meshes/link19_R.STL</uri>
            </mesh>
          </geometry>
        </collision>
        <visual name='R_ring_proximal_visual'>
          <pose>0 0 0 0 0 0</pose>
          <geometry>
            <mesh>
              <scale>1 1 1</scale>
              <uri>./h1_2_meshes/link19_R.STL</uri>
            </mesh>
          </geometry>
          <material>
            <diffuse>0.125 0.125 0.125 1</diffuse>
            <ambient>0.125 0.125 0.125 1</ambient>
          </material>
        </visual>
        <enable_wind>false</enable_wind>
      </link>
      <joint name='R_ring_intermediate_joint' type='revolute'>
        <pose>-8.3266726846886741e-17 3.3306690738754696e-16 1.3877787807814457e-17
          3.4694469519536142e-18 3.4694469519536142e-18 6.018531076210112e-36</pose>
        <parent>R_ring_proximal</parent>
        <child>R_ring_intermediate</child>
        <axis>
          <xyz>3.4694469519536142e-18 -3.4694469519536142e-18 1</xyz>
          <limit>
            <lower>0</lower>
            <upper>1.7</upper>
            <effort>1</effort>
            <velocity>0.5</velocity>
            <stiffness>100000000</stiffness>
            <dissipation>1</dissipation>
          </limit>
          <dynamics>
            <spring_reference>0</spring_reference>
            <spring_stiffness>0</spring_stiffness>
            <damping>0</damping>
            <friction>0</friction>
          </dynamics>
          <mimic joint='R_ring_proximal_joint' axis='axis'>
            <multiplier>1</multiplier>
            <offset>0</offset>
            <reference>0</reference>
          </mimic>
        </axis>
      </joint>
      <link name='R_ring_intermediate'>
        <pose>0.45685466525655233 -0.20736205800064889 0.086016169185084923 -0.052392653589793489
          -5.5511151231257827e-17 -1.5707963267948981</pose>
        <inertial>
          <pose>0.0021752999999999998 0.019567000000000001 -0.0050000000000000001 0 0 0</pose>
          <mass>0.0045683</mass>
          <inertia>
            <ixx>7.6285999999999999e-07</ixx>
            <ixy>8.0634999999999994e-08</ixy>
            <ixz>-6.1561999999999996e-13</ixz>
            <iyy>9.4310000000000002e-08</iyy>
            <iyz>5.8619000000000005e-13</iyz>
            <izz>7.8176999999999999e-07</izz>
          </inertia>
        </inertial>
        <collision name='R_ring_intermediate_collision'>
          <pose>0 0 0 0 0 0</pose>
          <geometry>
            <mesh>
              <scale>1 1 1</scale>
              <uri>./h1_2_meshes/link20_R.STL</uri>
            </mesh>
          </geometry>
        </collision>
        <visual name='R_ring_intermediate_visual'>
          <pose>0 0 0 0 0 0</pose>
          <geometry>
            <mesh>
              <scale>1 1 1</scale>
              <uri>./h1_2_meshes/link20_R.STL</uri>
            </mesh>
          </geometry>
          <material>
            <diffuse>0.125 0.125 0.125 1</diffuse>
            <ambient>0.125 0.125 0.125 1</ambient>
          </material>
        </visual>
        <enable_wind>false</enable_wind>
      </link>
      <joint name='R_thumb_proximal_yaw_joint' type='revolute'>
        <pose>5.5511151231257827e-17 -2.7755575615628914e-17 5.5511151231257827e-17
          7.3301664582073626e-44 -8.6509410083065088e-22 -1.6946518190724089e-22</pose>
        <parent>right_wrist_yaw_link</parent>
        <child>R_thumb_proximal_base</child>
        <axis>
          <xyz>8.6509410083065088e-22 -7.3301664582073626e-44 -1</xyz>
          <limit>
            <lower>-0.10000000000000001</lower>
            <upper>1.3</upper>
            <effort>1</effort>
            <velocity>0.5</velocity>
            <stiffness>100000000</stiffness>
            <dissipation>1</dissipation>
          </limit>
          <dynamics>
            <spring_reference>0</spring_reference>
            <spring_stiffness>0</spring_stiffness>
            <damping>0</damping>
            <friction>0</friction>
          </dynamics>
        </axis>
      </joint>
      <link name='R_thumb_proximal_base'>
        <pose>0.35709999999999992 -0.19253962800064889 0.11542994211456259 1.5707999998631261
          1.5707926535755432 1.5707963266739975</pose>
        <inertial>
          <pose>-0.0048063999999999997 0.00093820000000000004 -0.0075700000000000003 0 0 0</pose>
          <mass>0.0018868999999999999</mass>
          <inertia>
            <ixx>5.8159999999999999e-08</ixx>
            <ixy>1.4539e-08</ixy>
            <ixz>4.4910000000000003e-09</ixz>
            <iyy>7.9161000000000003e-08</iyy>
            <iyz>-1.8727e-09</iyz>
            <izz>6.7433000000000006e-08</izz>
          </inertia>
        </inertial>
        <collision name='R_thumb_proximal_base_collision'>
          <pose>0 0 0 0 0 0</pose>
          <geometry>
            <mesh>
              <scale>1 1 1</scale>
              <uri>./h1_2_meshes/link11_R.STL</uri>
            </mesh>
          </geometry>
        </collision>
        <visual name='R_thumb_proximal_base_visual'>
          <pose>0 0 0 0 0 0</pose>
          <geometry>
            <mesh>
              <scale>1 1 1</scale>
              <uri>./h1_2_meshes/link11_R.STL</uri>
            </mesh>
          </geometry>
          <material>
            <diffuse>0.125 0.125 0.125 1</diffuse>
            <ambient>0.125 0.125 0.125 1</ambient>
          </material>
        </visual>
        <enable_wind>false</enable_wind>
      </link>
      <joint name='R_thumb_proximal_pitch_joint' type='revolute'>
        <pose>-6.9388939039072284e-17 1.1102230246251565e-16 -8.3266726846886741e-17
          -5.5511151231257827e-17 5.5511151231257827e-17 -1.5407439555097887e-33</pose>
        <parent>R_thumb_proximal_base</parent>
        <child>R_thumb_proximal</child>
        <axis>
          <xyz>5.5511151231257827e-17 5.5511151231257827e-17 1</xyz>
          <limit>
            <lower>-0.10000000000000001</lower>
            <upper>0.59999999999999998</upper>
            <effort>1</effort>
            <velocity>0.5</velocity>
            <stiffness>100000000</stiffness>
            <dissipation>1</dissipation>
          </limit>
          <dynamics>
            <spring_reference>0</spring_reference>
            <spring_stiffness>0</spring_stiffness>
            <damping>0</damping>
            <friction>0</friction>
          </dynamics>
        </axis>
      </joint>
      <link name='R_thumb_proximal'>
        <pose>0.34785004000876768 -0.18164762638421203 0.12423988212333326 -3.1415889803363513
          -1.2879073464244568 1.5707926535291257</pose>
        <inertial>
          <pose>0.021932 0.012784999999999999 -0.0080385999999999999 0 0 0</pose>
          <mass>0.0066074999999999997</mass>
          <inertia>
            <ixx>1.5685999999999999e-06</ixx>
            <ixy>-7.8296000000000002e-07</ixy>
            <ixz>8.9142999999999999e-10</ixz>
            <iyy>1.7352999999999999e-06</iyy>
            <iyz>-1.0190999999999999e-09</iyz>
            <izz>2.7860000000000001e-06</izz>
          </inertia>
        </inertial>
        <collision name='R_thumb_proximal_collision'>
          <pose>0 0 0 0 0 0</pose>
          <geometry>
            <mesh>
              <scale>1 1 1</scale>
              <uri>./h1_2_meshes/link12_R.STL</uri>
            </mesh>
          </geometry>
        </collision>
        <visual name='R_thumb_proximal_visual'>
          <pose>0 0 0 0 0 0</pose>
          <geometry>
            <mesh>
              <scale>1 1 1</scale>
              <uri>./h1_2_meshes/link12_R.STL</uri>
            </mesh>
          </geometry>
          <material>
            <diffuse>0.125 0.125 0.125 1</diffuse>
            <ambient>0.125 0.125 0.125 1</ambient>
          </material>
        </visual>
        <enable_wind>false</enable_wind>
      </link>
      <joint name='R_thumb_intermediate_joint' type='revolute'>
        <pose>-9.7144514654701197e-17 1.6653345369377348e-16 -8.3266726846886741e-17
          -5.5511151231257827e-17 5.5511151231257827e-17 -1.5407439555097887e-33</pose>
        <parent>R_thumb_proximal</parent>
        <child>R_thumb_intermediate</child>
        <axis>
          <xyz>5.5511151231257827e-17 5.5511151231257827e-17 1</xyz>
          <limit>
            <lower>0</lower>
            <upper>0.80000000000000004</upper>
            <effort>1</effort>
            <velocity>0.5</velocity>
            <stiffness>100000000</stiffness>
            <dissipation>1</dissipation>
          </limit>
          <dynamics>
            <spring_reference>0</spring_reference>
            <spring_stiffness>0</spring_stiffness>
            <damping>0</damping>
            <friction>0</friction>
          </dynamics>
          <mimic joint='R_thumb_proximal_pitch_joint' axis='axis'>
            <multiplier>1.6000000000000001</multiplier>
            <offset>0</offset>
            <reference>0</reference>
          </mimic>
        </axis>
      </joint>
      <link name='R_thumb_intermediate'>
        <pose>0.38240308531148953 -0.17011453237991919 0.16678150306090633 -3.1415889803363495
          -1.2879073464244568 1.570792653529125</pose>
        <inertial>
          <pose>0.0095543999999999994 -0.0016282 -0.0071996999999999998 0 0 0</pose>
          <mass>0.0037847000000000002</mass>
          <inertia>
            <ixx>3.6981e-07</ixx>
            <ixy>-9.8581000000000001e-08</ixy>
            <ixz>-4.7469000000000003e-12</ixz>
            <iyy>3.2393999999999997e-07</iyy>
            <iyz>1.0939e-12</iyz>
            <izz>4.6530999999999998e-07</izz>
          </inertia>
        </inertial>
        <collision name='R_thumb_intermediate_collision'>
          <pose>0 0 0 0 0 0</pose>
          <geometry>
            <mesh>
              <scale>1 1 1</scale>
              <uri>./h1_2_meshes/link13_R.STL</uri>
            </mesh>
          </geometry>
        </collision>
        <visual name='R_thumb_intermediate_visual'>
          <pose>0 0 0 0 0 0</pose>
          <geometry>
            <mesh>
              <scale>1 1 1</scale>
              <uri>./h1_2_meshes/link13_R.STL</uri>
            </mesh>
          </geometry>
          <material>
            <diffuse>0.125 0.125 0.125 1</diffuse>
            <ambient>0.125 0.125 0.125 1</ambient>
          </material>
        </visual>
        <enable_wind>false</enable_wind>
      </link>
      <joint name='R_thumb_distal_joint' type='revolute'>
        <pose>2.7755575615628914e-17 2.2204460492503131e-16 -8.3266726846886741e-17
          -5.5511151231257827e-17 5.5511151231257827e-17 -1.5407439555097887e-33</pose>
        <parent>R_thumb_intermediate</parent>
        <child>R_thumb_distal</child>
        <axis>
          <xyz>5.5511151231257827e-17 5.5511151231257827e-17 1</xyz>
          <limit>
            <lower>0</lower>
            <upper>1.2</upper>
            <effort>1</effort>
            <velocity>0.5</velocity>
            <stiffness>100000000</stiffness>
            <dissipation>1</dissipation>
          </limit>
          <dynamics>
            <spring_reference>0</spring_reference>
            <spring_stiffness>0</spring_stiffness>
            <damping>0</damping>
            <friction>0</friction>
          </dynamics>
          <mimic joint='R_thumb_proximal_pitch_joint' axis='axis'>
            <multiplier>2.3999999999999999</multiplier>
            <offset>0</offset>
            <reference>0</reference>
          </mimic>
        </axis>
      </joint>
      <link name='R_thumb_distal'>
        <pose>0.39255910624739493 -0.16561499380094741 0.18655965341238767 -3.1415889803363446
          -1.2879073464244561 1.570792653529121</pose>
        <inertial>
          <pose>0.0092887999999999998 0.0049528999999999997 -0.0060032999999999996 0 0 0</pose>
          <mass>0.0033441</mass>
          <inertia>
            <ixx>1.3631999999999999e-07</ixx>
            <ixy>-5.6787999999999999e-08</ixy>
            <ixz>-9.2763999999999994e-11</ixz>
            <iyy>1.4051999999999999e-07</iyy>
            <iyz>-1.2283e-10</iyz>
            <izz>2.0025999999999999e-07</izz>
          </inertia>
        </inertial>
        <collision name='R_thumb_distal_collision'>
          <pose>0 0 0 0 0 0</pose>
          <geometry>
            <mesh>
              <scale>1 1 1</scale>
              <uri>./h1_2_meshes/link14_R.STL</uri>
            </mesh>
          </geometry>
        </collision>
        <visual name='R_thumb_distal_visual'>
          <pose>0 0 0 0 0 0</pose>
          <geometry>
            <mesh>
              <scale>1 1 1</scale>
              <uri>./h1_2_meshes/link14_R.STL</uri>
            </mesh>
          </geometry>
          <material>
            <diffuse>0.125 0.125 0.125 1</diffuse>
            <ambient>0.125 0.125 0.125 1</ambient>
          </material>
        </visual>
        <enable_wind>false</enable_wind>
      </link>
      <frame name='camera_joint' attached_to='torso_link'>
        <pose>0.11108999999999999 0.017500000000000002 0.68789 0 0.88592912831232185 0</pose>
      </frame>
      <frame name='camera_link' attached_to='camera_joint'>
        <pose>0 0 0 0 0 0</pose>
      </frame>
      <frame name='imu_joint' attached_to='torso_link'>
        <pose>-0.044519999999999997 -0.01891 0.27755999999999997 0 0 0</pose>
      </frame>
      <frame name='imu_link' attached_to='imu_joint'>
        <pose>0 0 0 0 0 0</pose>
      </frame>
      <frame name='lidar_joint' attached_to='torso_link'>
        <pose>0.048739999999999999 0 0.67979999999999996 0 0.24015730507442007 0</pose>
      </frame>
      <frame name='lidar_link' attached_to='lidar_joint'>
        <pose>0 0 0 0 0 0</pose>
      </frame>
      <frame name='logo_joint' attached_to='torso_link'>
        <pose>0 0 0 0 0 0</pose>
      </frame>
      <frame name='logo_link' attached_to='logo_joint'>
        <pose>0 0 0 0 0 0</pose>
      </frame>
      <frame name='L_base_link_joint' attached_to='left_wrist_yaw_link'>
        <pose>0.053999999999999999 0 0 0 0 1.5707963267948959</pose>
      </frame>
      <frame name='L_hand_base_link' attached_to='L_base_link_joint'>
        <pose>0 0 0 0 0 0</pose>
      </frame>
      <frame name='R_base_link_joint' attached_to='right_wrist_yaw_link'>
        <pose>0.053999999999999999 0 0 3.1415926535897931 0 -1.5707963267948959</pose>
      </frame>
      <frame name='R_hand_base_link' attached_to='R_base_link_joint'>
        <pose>0 0 0 0 0 0</pose>
      </frame>
      <plugin name='gz::sim::systems::ApplyJointsForces'
        filename='gz-sim-apply-joints-forces-system'>
        <joint_name>L_index_intermediate_joint</joint_name>
        <joint_name>L_index_proximal_joint</joint_name>
        <joint_name>L_middle_intermediate_joint</joint_name>
        <joint_name>L_middle_proximal_joint</joint_name>
        <joint_name>L_pinky_intermediate_joint</joint_name>
        <joint_name>L_pinky_proximal_joint</joint_name>
        <joint_name>L_ring_intermediate_joint</joint_name>
        <joint_name>L_ring_proximal_joint</joint_name>
        <joint_name>L_thumb_intermediate_joint</joint_name>
        <joint_name>L_thumb_proximal_yaw_joint</joint_name>
        <joint_name>L_thumb_distal_joint</joint_name>
        <joint_name>L_thumb_proximal_pitch_joint</joint_name>
        <joint_name>R_index_intermediate_joint</joint_name>
        <joint_name>R_index_proximal_joint</joint_name>
        <joint_name>R_middle_intermediate_joint</joint_name>
        <joint_name>R_middle_proximal_joint</joint_name>
        <joint_name>R_pinky_intermediate_joint</joint_name>
        <joint_name>R_pinky_proximal_joint</joint_name>
        <joint_name>R_ring_intermediate_joint</joint_name>
        <joint_name>R_ring_proximal_joint</joint_name>
        <joint_name>R_thumb_intermediate_joint</joint_name>
        <joint_name>R_thumb_proximal_yaw_joint</joint_name>
        <joint_name>R_thumb_distal_joint</joint_name>
        <joint_name>R_thumb_proximal_pitch_joint</joint_name>
        <joint_name>left_hip_yaw_joint</joint_name>
        <joint_name>left_hip_pitch_joint</joint_name>
        <joint_name>left_hip_roll_joint</joint_name>
        <joint_name>left_knee_joint</joint_name>
        <joint_name>left_ankle_pitch_joint</joint_name>
        <joint_name>left_ankle_roll_joint</joint_name>
        <joint_name>right_hip_yaw_joint</joint_name>
        <joint_name>right_hip_pitch_joint</joint_name>
        <joint_name>right_hip_roll_joint</joint_name>
        <joint_name>right_knee_joint</joint_name>
        <joint_name>right_ankle_pitch_joint</joint_name>
        <joint_name>right_ankle_roll_joint</joint_name>
        <joint_name>left_shoulder_pitch_joint</joint_name>
        <joint_name>left_shoulder_roll_joint</joint_name>
        <joint_name>left_shoulder_yaw_joint</joint_name>
        <joint_name>left_elbow_joint</joint_name>
        <joint_name>left_wrist_roll_joint</joint_name>
        <joint_name>left_wrist_pitch_joint</joint_name>
        <joint_name>left_wrist_yaw_joint</joint_name>
        <joint_name>right_shoulder_pitch_joint</joint_name>
        <joint_name>right_shoulder_roll_joint</joint_name>
        <joint_name>right_shoulder_yaw_joint</joint_name>
        <joint_name>right_elbow_joint</joint_name>
        <joint_name>right_wrist_roll_joint</joint_name>
        <joint_name>right_wrist_pitch_joint</joint_name>
        <joint_name>right_wrist_yaw_joint</joint_name>
        <joint_name>torso_joint</joint_name>
        <topic>cmd_forces</topic>
      </plugin>
      <plugin name='gz::sim::systems::JointStatePublisher'
        filename='gz-sim-joint-state-publisher-system' />
      <pose>0 0 1.0433790683746338 0 0 0</pose>
      <static>false</static>
      <self_collide>false</self_collide>
    </model>
    <light name='sun' type='directional'>
      <pose>0 0 10 0 0 0</pose>
      <cast_shadows>true</cast_shadows>
      <intensity>1</intensity>
      <direction>-0.5 0.10000000000000001 -0.90000000000000002</direction>
      <diffuse>0.800000012 0.800000012 0.800000012 1</diffuse>
      <specular>0.200000003 0.200000003 0.200000003 1</specular>
      <attenuation>
        <range>1000</range>
        <linear>0.01</linear>
        <constant>0.90000000000000002</constant>
        <quadratic>0.001</quadratic>
      </attenuation>
      <spot>
        <inner_angle>0</inner_angle>
        <outer_angle>0</outer_angle>
        <falloff>0</falloff>
      </spot>
    </light>
  </world>
</sdf>
